Workbook

Sheet report
FE1: 보고일자 : 2020-06-03 | FM1: 보고일자 : 2020-06-10 | FU1: 보고일자 : 2020-06-17 | GC1: 보고일자 : 2020-06-25 | GK1: 보고일자 : 2020-07-01 | GS1: 보고일자 : 2020-07-08 | HA1: 보고일자 : 2020-07-15 | HI1: 보고일자 : 2020-07-22 | HQ1: 보고일자 : 2020-07-29 | HY1: 보고일자 : 2020-08-05 | IG1: 보고일자 : 2020-08-12 | IO1: 보고일자 : 2020-08-19 | IW1: 보고일자 : 2020-08-26 | JE1: 보고일자 : 2020-09-02 | JM1: 보고일자 : 2020-09-09 | JU1: 보고일자 : 2020-09-16 | KC1: 보고일자 : 2020-09-23 | KK1: 보고일자 : 2020-09-30 | KS1: 보고일자 : 2020-10-07 | LA1: 보고일자 : 2020-10-14 | LI1: 보고일자 : 2020-10-21 | LQ1: 보고일자 : 2020-10-28 | LY1: 보고일자 : 2020-11-04 | MG1: 보고일자 : 2020-11-11 | MO1: 보고일자 : 2020-11-18 | MW1: 보고일자 : 2020-11-25 | NE1: 보고일자 : 2020-12-2 | NM1: 보고일자 : 2020-12-9 | NU1: 보고일자 : 2020-12-16 | OC1: 보고일자 : 2020-12-23 | OK1: 보고일자 : 2020-12-30
FE3: 쇠고기/미국 | FM3: 쇠고기/미국 | FU3: 쇠고기/미국 | GC3: 쇠고기/미국 | GK3: 쇠고기/미국 | GS3: 쇠고기/미국 | HA3: 쇠고기/미국 | HI3: 쇠고기/미국 | HQ3: 쇠고기/미국 | HY3: 쇠고기/미국 | IG3: 쇠고기/미국 | IO3: 쇠고기/미국 | IW3: 쇠고기/미국 | JE3: 쇠고기/미국 | JM3: 쇠고기/미국 | JU3: 쇠고기/미국 | KC3: 쇠고기/미국 | KK3: 쇠고기/미국 | KS3: 쇠고기/미국 | LA3: 쇠고기/미국 | LI3: 쇠고기/미국 | LQ3: 쇠고기/미국 | LY3: 쇠고기/미국 | MG3: 쇠고기/미국 | MO3: 쇠고기/미국 | MW3: 쇠고기/미국 | NE3: 쇠고기/미국 | NM3: 쇠고기/미국 | NU3: 쇠고기/미국 | OC3: 쇠고기/미국 | OK3: 쇠고기/미국
FE4: 구분 | FG4: 2019년 | FH4: 2020년 | FJ4: 전주 | FK4: 전년 | FM4: 구분 | FO4: 2019년 | FP4: 2020년 | FR4: 전주 | FS4: 전년 | FU4: 구분 | FW4: 2019년 | FX4: 2020년 | FZ4: 전주 | GA4: 전년 | GC4: 구분 | GE4: 2019년 | GF4: 2020년 | GH4: 전주 | GI4: 전년 | GK4: 구분 | GM4: 2019년 | GN4: 2020년 | GP4: 전주 | GQ4: 전년 | GS4: 구분 | GU4: 2019년 | GV4: 2020년 | GX4: 전주 | GY4: 전년 | HA4: 구분 | HC4: 2019년 | HD4: 2020년 | HF4: 전주 | HG4: 전년 | HI4: 구분 | HK4: 2019년 | HL4: 2020년 | HN4: 전주 | HO4: 전년 | HQ4: 구분 | HS4: 2019년 | HT4: 2020년 | HV4: 전주 | HW4: 전년 | HY4: 구분 | IA4: 2019년 | IB4: 2020년 | ID4: 전주 | IE4: 전년 | IG4: 구분 | II4: 2019년 | IJ4: 2020년 | IL4: 전주 | IM4: 전년 | IO4: 구분 | IQ4: 2019년 | IR4: 2020년 | IT4: 전주 | IU4: 전년 | IW4: 구분 | IY4: 2019년 | IZ4: 2020년 | JB4: 전주 | JC4: 전년 | JE4: 구분 | JG4: 2019년 | JH4: 2020년 | JJ4: 전주 | JK4: 전년 | JM4: 구분 | JO4: 2019년 | JP4: 2020년 | JR4: 전주 | JS4: 전년 | JU4: 구분 | JW4: 2019년 | JX4: 2020년 | JZ4: 전주 | KA4: 전년 | KC4: 구분 | KE4: 2019년 | KF4: 2020년 | KH4: 전주 | KI4: 전년 | KK4: 구분 | KM4: 2019년 | KN4: 2020년 | KP4: 전주 | KQ4: 전년 | KS4: 구분 | KU4: 2019년 | KV4: 2020년 | KX4: 전주 | KY4: 전년 | LA4: 구분 | LC4: 2019년 | LD4: 2020년 | LF4: 전주 | LG4: 전년 | LI4: 구분 | LK4: 2019년 | LL4: 2020년 | LN4: 전주 | LO4: 전년 | LQ4: 구분 | LS4: 2019년 | LT4: 2020년 | LV4: 전주 | LW4: 전년 | LY4: 구분 | MA4: 2019년 | MB4: 2020년 | MD4: 전주 | ME4: 전년 | MG4: 구분 | MI4: 2019년 | MJ4: 2020년 | ML4: 전주 | MM4: 전년 | MO4: 구분 | MQ4: 2019년 | MR4: 2020년 | MT4: 전주 | MU4: 전년 | MW4: 구분 | MY4: 2019년 | MZ4: 2020년 | NB4: 전주 | NC4: 전년 | NE4: 구분 | NG4: 2019년 | NH4: 2020년 | NJ4: 전주 | NK4: 전년 | NM4: 구분 | NO4: 2019년 | NP4: 2020년 | NR4: 전주 | NS4: 전년 | NU4: 구분 | NW4: 2019년 | NX4: 2020년 | NZ4: 전주 | OA4: 전년 | OC4: 구분 | OE4: 2019년 | OF4: 2020년 | OH4: 전주 | OI4: 전년 | OK4: 구분 | OM4: 2019년 | ON4: 2020년 | OP4: 전주 | OQ4: 전년
FG5: 5월4주 | FH5: 5월3주 | FI5: 5월4주 | FJ5: 대비 | FK5: 대비 | FO5: 6월1주 | FP5: 5월4주 | FQ5: 6월1주 | FR5: 대비 | FS5: 대비 | FW5: 6월2주 | FX5: 6월1주 | FY5: 6월2주 | FZ5: 대비 | GA5: 대비 | GE5: 6월3주 | GF5: 6월2주 | GG5: 6월3주 | GH5: 대비 | GI5: 대비 | GM5: 6월4주 | GN5: 6월3주 | GO5: 6월4주 | GP5: 대비 | GQ5: 대비 | GU5: 7월1주 | GV5: 6월4주 | GW5: 7월1주 | GX5: 대비 | GY5: 대비 | HC5: 7월2주 | HD5: 7월1주 | HE5: 7월2주 | HF5: 대비 | HG5: 대비 | HK5: 7월3주 | HL5: 7월2주 | HM5: 7월3주 | HN5: 대비 | HO5: 대비 | HS5: 7월 4주 | HT5: 7월3주 | HU5: 7월 4주 | HV5: 대비 | HW5: 대비 | IA5: 7월 5주 | IB5: 7월 4주 | IC5: 7월 5주 | ID5: 대비 | IE5: 대비 | II5: 8월 1주 | IJ5: 7월 5주 | IK5: 8월 1주 | IL5: 대비 | IM5: 대비 | IQ5: 8월 2주 | IR5: 8월 1주 | IS5: 8월 2주 | IT5: 대비 | IU5: 대비 | IY5: 8월 3주 | IZ5: 8월 2주 | JA5: 8월 3주 | JB5: 대비 | JC5: 대비 | JG5: 8월 4주 | JH5: 8월 3주 | JI5: 8월 4주 | JJ5: 대비 | JK5: 대비 | JO5: 9월 1주 | JP5: 8월 4주 | JQ5: 9월 1주 | JR5: 대비 | JS5: 대비 | JW5: 9월 2주 | JX5: 9월 1주 | JY5: 9월 2주 | JZ5: 대비 | KA5: 대비 | KE5: 9월 3주 | KF5: 9월 2주 | KG5: 9월 3주 | KH5: 대비 | KI5: 대비 | KM5: 9월 4주 | KN5: 9월 3주 | KO5: 9월 4주 | KP5: 대비 | KQ5: 대비 | KU5: 9월 5주 | KV5: 9월 4주 | KW5: 9월 5주 | KX5: 대비 | KY5: 대비 | LC5: 10월1주 | LD5: 9월 5주 | LE5: 10월1주 | LF5: 대비 | LG5: 대비 | LK5: 10월2주 | LL5: 10월1주 | LM5: 10월2주 | LN5: 대비 | LO5: 대비 | LS5: 10월3주 | LT5: 10월2주 | LU5: 10월3주 | LV5: 대비 | LW5: 대비 | MA5: 10월4주 | MB5: 10월3주 | MC5: 10월4주 | MD5: 대비 | ME5: 대비 | MI5: 11월1주 | MJ5: 10월4주 | MK5: 11월1주 | ML5: 대비 | MM5: 대비 | MQ5: 11월2주 | MR5: 11월1주 | MS5: 11월2주 | MT5: 대비 | MU5: 대비 | MY5: 11월3주 | MZ5: 11월2주 | NA5: 11월3주 | NB5: 대비 | NC5: 대비 | NG5: 11월4주 | NH5: 11월3주 | NI5: 11월4주 | NJ5: 대비 | NK5: 대비 | NO5: 12월1주 | NP5: 11월4주 | NQ5: 12월1주 | NR5: 대비 | NS5: 대비 | NW5: 12월2주 | NX5: 12월1주 | NY5: 12월2주 | NZ5: 대비 | OA5: 대비 | OE5: 12월3주 | OF5: 12월2주 | OG5: 12월3주 | OH5: 대비 | OI5: 대비 | OM5: 12월4주 | ON5: 12월3주 | OO5: 12월4주 | OP5: 대비 | OQ5: 대비
FE6: 수급 | FF6: 도축(천두) | FG6: 641 | FH6: 555 | FI6: 524 | FJ6: =(FI6-FH6)/FH6 -> -0.055855856 | FK6: =(FI6-FG6)/FG6 -> -0.1825273 | FM6: 수급 | FN6: 도축(천두) | FO6: 582 | FP6: 524 | FQ6: 636 | FR6: =(FQ6-FP6)/FP6 -> 0.21374046 | FS6: =(FQ6-FO6)/FO6 -> 0.092783505 | FU6: 수급 | FV6: 도축(천두) | FW6: 662 | FX6: 636 | FY6: 658 | FZ6: =(FY6-FX6)/FX6 -> 0.034591195 | GA6: =(FY6-FW6)/FW6 -> -0.0060422961 | GC6: 수급 | GD6: 도축(천두) | GE6: 665 | GF6: 658 | GG6: 656 | GH6: =(GG6-GF6)/GF6 -> -0.0030395137 | GI6: =(GG6-GE6)/GE6 -> -0.013533835 | GK6: 수급 | GL6: 도축(천두) | GM6: 662 | GN6: 656 | GO6: 680 | GP6: =(GO6-GN6)/GN6 -> 0.036585366 | GQ6: =(GO6-GM6)/GM6 -> 0.027190332 | GS6: 수급 | GT6: 도축(천두) | GU6: 665 | GV6: 680 | GW6: 593 | GX6: =(GW6-GV6)/GV6 -> -0.12794118 | GY6: =(GW6-GU6)/GU6 -> -0.10827068 | HA6: 수급 | HB6: 도축(천두) | HC6: 573 | HD6: 593 | HE6: 657 | HF6: =(HE6-HD6)/HD6 -> 0.1079258 | HG6: =(HE6-HC6)/HC6 -> 0.14659686 | HI6: 수급 | HJ6: 도축(천두) | HK6: 655 | HL6: 657 | HM6: 650 | HN6: =(HM6-HL6)/HL6 -> -0.01065449 | HO6: =(HM6-HK6)/HK6 -> -0.0076335878 | HQ6: 수급 | HR6: 도축(천두) | HS6: 651 | HT6: 650 | HU6: 646 | HV6: =(HU6-HT6)/HT6 -> -0.0061538462 | HW6: =(HU6-HS6)/HS6 -> -0.0076804916 | HY6: 수급 | HZ6: 도축(천두) | IA6: 651 | IB6: 646 | IC6: 638 | ID6: =(IC6-IB6)/IB6 -> -0.012383901 | IE6: =(IC6-IA6)/IA6 -> -0.019969278 | IG6: 수급 | IH6: 도축(천두) | II6: 626 | IJ6: 638 | IK6: 633 | IL6: =(IK6-IJ6)/IJ6 -> -0.0078369906 | IM6: =(IK6-II6)/II6 -> 0.011182109 | IO6: 수급 | IP6: 도축(천두) | IQ6: 645 | IR6: 633 | IS6: 640 | IT6: =(IS6-IR6)/IR6 -> 0.011058452 | IU6: =(IS6-IQ6)/IQ6 -> -0.007751938 | IW6: 수급 | IX6: 도축(천두) | IY6: 651 | IZ6: 640 | JA6: 652 | JB6: =(JA6-IZ6)/IZ6 -> 0.01875 | JC6: =(JA6-IY6)/IY6 -> 0.0015360983 | JE6: 수급 | JF6: 도축(천두) | JG6: 654 | JH6: 652 | JI6: 654 | JJ6: =(JI6-JH6)/JH6 -> 0.0030674847 | JK6: =(JI6-JG6)/JG6 -> 0 | JM6: 수급 | JN6: 도축(천두) | JO6: 644 | JP6: 654 | JQ6: 633 | JR6: =(JQ6-JP6)/JP6 -> -0.032110092 | JS6: =(JQ6-JO6)/JO6 -> -0.017080745 | JU6: 수급 | JV6: 도축(천두) | JW6: 565 | JX6: 633 | JY6: 574 | JZ6: =(JY6-JX6)/JX6 -> -0.093206951 | KA6: =(JY6-JW6)/JW6 -> 0.015929204 | KC6: 수급 | KD6: 도축(천두) | KE6: 629 | KF6: 574 | KG6: 645 | KH6: =(KG6-KF6)/KF6 -> 0.12369338 | KI6: =(KG6-KE6)/KE6 -> 0.025437202 | KK6: 수급 | KL6: 도축(천두) | KM6: 658 | KN6: 645 | KO6: 651 | KP6: =(KO6-KN6)/KN6 -> 0.0093023256 | KQ6: =(KO6-KM6)/KM6 -> -0.010638298 | KS6: 수급 | KT6: 도축(천두) | KU6: 648 | KV6: 651 | KW6: 665 | KX6: =(KW6-KV6)/KV6 -> 0.021505376 | KY6: =(KW6-KU6)/KU6 -> 0.026234568 | LA6: 수급 | LB6: 도축(천두) | LC6: 639 | LD6: 665 | LE6: 637 | LF6: =(LE6-LD6)/LD6 -> -0.042105263 | LG6: =(LE6-LC6)/LC6 -> -0.0031298905 | LI6: 수급 | LJ6: 도축(천두) | LK6: 645 | LL6: 637 | LM6: 654 | LN6: =(LM6-LL6)/LL6 -> 0.026687598 | LO6: =(LM6-LK6)/LK6 -> 0.013953488 | LQ6: 수급 | LR6: 도축(천두) | LS6: 642 | LT6: 654 | LU6: 643 | LV6: =(LU6-LT6)/LT6 -> -0.016819572 | LW6: =(LU6-LS6)/LS6 -> 0.0015576324 | LY6: 수급 | LZ6: 도축(천두) | MA6: 640 | MB6: 643 | MC6: 638 | MD6: =(MC6-MB6)/MB6 -> -0.0077760498 | ME6: =(MC6-MA6)/MA6 -> -0.003125 | MG6: 수급 | MH6: 도축(천두) | MI6: 655 | MJ6: 638 | MK6: 647 | ML6: =(MK6-MJ6)/MJ6 -> 0.014106583 | MM6: =(MK6-MI6)/MI6 -> -0.01221374 | MO6: 수급 | MP6: 도축(천두) | MQ6: 651 | MR6: 647 | MS6: 653 | MT6: =(MS6-MR6)/MR6 -> 0.0092735703 | MU6: =(MS6-MQ6)/MQ6 -> 0.0030721966 | MW6: 수급 | MX6: 도축(천두) | MY6: 657 | MZ6: 653 | NA6: 665 | NB6: =(NA6-MZ6)/MZ6 -> 0.018376723 | NC6: =(NA6-MY6)/MY6 -> 0.01217656 | NE6: 수급 | NF6: 도축(천두) | NG6: 662 | NH6: 665 | NI6: 564 | NJ6: =(NI6-NH6)/NH6 -> -0.1518797 | NK6: =(NI6-NG6)/NG6 -> -0.14803625 | NM6: 수급 | NN6: 도축(천두) | NO6: 556 | NP6: 564 | NQ6: 667 | NR6: =(NQ6-NP6)/NP6 -> 0.18262411 | NS6: =(NQ6-NO6)/NO6 -> 0.19964029 | NU6: 수급 | NV6: 도축(천두) | NW6: 679 | NX6: 667 | NY6: 665 | NZ6: =(NY6-NX6)/NX6 -> -0.0029985007 | OA6: =(NY6-NW6)/NW6 -> -0.020618557 | OC6: 수급 | OD6: 도축(천두) | OE6: 662 | OF6: 665 | OG6: 659 | OH6: =(OG6-OF6)/OF6 -> -0.0090225564 | OI6: =(OG6-OE6)/OE6 -> -0.0045317221 | OK6: 수급 | OL6: 도축(천두) | OM6: 668 | ON6: 659 | OO6: 419 | OP6: =(OO6-ON6)/ON6 -> -0.36418816 | OQ6: =(OO6-OM6)/OM6 -> -0.37275449
FF7: 수출(천톤) | FJ7: =(FI7-FH7)/FH7 -> #DIV/0! | FK7: =(FI7-FG7)/FG7 -> #DIV/0! | FN7: 수출(천톤) | FR7: =(FQ7-FP7)/FP7 -> #DIV/0! | FS7: =(FQ7-FO7)/FO7 -> #DIV/0! | FV7: 수출(천톤) | FZ7: =(FY7-FX7)/FX7 -> #DIV/0! | GA7: =(FY7-FW7)/FW7 -> #DIV/0! | GD7: 수출(천톤) | GH7: =(GG7-GF7)/GF7 -> #DIV/0! | GI7: =(GG7-GE7)/GE7 -> #DIV/0! | GL7: 수출(천톤) | GP7: =(GO7-GN7)/GN7 -> #DIV/0! | GQ7: =(GO7-GM7)/GM7 -> #DIV/0! | GT7: 수출(천톤) | GX7: =(GW7-GV7)/GV7 -> #DIV/0! | GY7: =(GW7-GU7)/GU7 -> #DIV/0! | HB7: 수출(천톤) | HF7: =(HE7-HD7)/HD7 -> #DIV/0! | HG7: =(HE7-HC7)/HC7 -> #DIV/0! | HJ7: 수출(천톤) | HN7: =(HM7-HL7)/HL7 -> #DIV/0! | HO7: =(HM7-HK7)/HK7 -> #DIV/0! | HR7: 수출(천톤) | HV7: =(HU7-HT7)/HT7 -> #DIV/0! | HW7: =(HU7-HS7)/HS7 -> #DIV/0! | HZ7: 수출(천톤) | ID7: =(IC7-IB7)/IB7 -> #DIV/0! | IE7: =(IC7-IA7)/IA7 -> #DIV/0! | IH7: 수출(천톤) | IL7: =(IK7-IJ7)/IJ7 -> #DIV/0! | IM7: =(IK7-II7)/II7 -> #DIV/0! | IP7: 수출(천톤) | IT7: =(IS7-IR7)/IR7 -> #DIV/0! | IU7: =(IS7-IQ7)/IQ7 -> #DIV/0! | IX7: 수출(천톤) | JB7: =(JA7-IZ7)/IZ7 -> #DIV/0! | JC7: =(JA7-IY7)/IY7 -> #DIV/0! | JF7: 수출(천톤) | JJ7: =(JI7-JH7)/JH7 -> #DIV/0! | JK7: =(JI7-JG7)/JG7 -> #DIV/0! | JN7: 수출(천톤) | JR7: =(JQ7-JP7)/JP7 -> #DIV/0! | JS7: =(JQ7-JO7)/JO7 -> #DIV/0! | JV7: 수출(천톤) | JZ7: =(JY7-JX7)/JX7 -> #DIV/0! | KA7: =(JY7-JW7)/JW7 -> #DIV/0! | KD7: 수출(천톤) | KH7: =(KG7-KF7)/KF7 -> #DIV/0! | KI7: =(KG7-KE7)/KE7 -> #DIV/0! | KL7: 수출(천톤) | KP7: =(KO7-KN7)/KN7 -> #DIV/0! | KQ7: =(KO7-KM7)/KM7 -> #DIV/0! | KT7: 수출(천톤) | KX7: =(KW7-KV7)/KV7 -> #DIV/0! | KY7: =(KW7-KU7)/KU7 -> #DIV/0! | LB7: 수출(천톤) | LF7: =(LE7-LD7)/LD7 -> #DIV/0! | LG7: =(LE7-LC7)/LC7 -> #DIV/0! | LJ7: 수출(천톤) | LN7: =(LM7-LL7)/LL7 -> #DIV/0! | LO7: =(LM7-LK7)/LK7 -> #DIV/0! | LR7: 수출(천톤) | LV7: =(LU7-LT7)/LT7 -> #DIV/0! | LW7: =(LU7-LS7)/LS7 -> #DIV/0! | LZ7: 수출(천톤) | MD7: =(MC7-MB7)/MB7 -> #DIV/0! | ME7: =(MC7-MA7)/MA7 -> #DIV/0! | MH7: 수출(천톤) | ML7: =(MK7-MJ7)/MJ7 -> #DIV/0! | MM7: =(MK7-MI7)/MI7 -> #DIV/0! | MP7: 수출(천톤) | MT7: =(MS7-MR7)/MR7 -> #DIV/0! | MU7: =(MS7-MQ7)/MQ7 -> #DIV/0! | MX7: 수출(천톤) | NB7: =(NA7-MZ7)/MZ7 -> #DIV/0! | NC7: =(NA7-MY7)/MY7 -> #DIV/0! | NF7: 수출(천톤) | NJ7: =(NI7-NH7)/NH7 -> #DIV/0! | NK7: =(NI7-NG7)/NG7 -> #DIV/0! | NN7: 수출(천톤) | NR7: =(NQ7-NP7)/NP7 -> #DIV/0! | NS7: =(NQ7-NO7)/NO7 -> #DIV/0! | NV7: 수출(천톤) | NZ7: =(NY7-NX7)/NX7 -> #DIV/0! | OA7: =(NY7-NW7)/NW7 -> #DIV/0! | OD7: 수출(천톤) | OH7: =(OG7-OF7)/OF7 -> #DIV/0! | OI7: =(OG7-OE7)/OE7 -> #DIV/0! | OL7: 수출(천톤) | OP7: =(OO7-ON7)/ON7 -> #DIV/0! | OQ7: =(OO7-OM7)/OM7 -> #DIV/0!
FE8: 가격 | FF8: 생우($/lb) | FG8: 1.16 | FH8: 1.17 | FI8: 1.16 | FJ8: =(FI8-FH8)/FH8 -> -0.0085470085 | FK8: =(FI8-FG8)/FG8 -> 0 | FM8: 가격 | FN8: 지육($/kg) | FR8: =(FQ8-FP8)/FP8 -> #DIV/0! | FS8: =(FQ8-FO8)/FO8 -> #DIV/0! | FU8: 가격 | FV8: 지육($/kg) | FZ8: =(FY8-FX8)/FX8 -> #DIV/0! | GA8: =(FY8-FW8)/FW8 -> #DIV/0! | GC8: 가격 | GD8: 지육($/kg) | GE8: 4.89 | GF8: 5.31 | GG8: 4.85 | GH8: =(GG8-GF8)/GF8 -> -0.086629002 | GI8: =(GG8-GE8)/GE8 -> -0.0081799591 | GK8: 가격 | GL8: 지육($/kg) | GM8: 4.87 | GN8: 4.85 | GO8: 4.63 | GP8: =(GO8-GN8)/GN8 -> -0.045360825 | GQ8: =(GO8-GM8)/GM8 -> -0.049281314 | GS8: 가격 | GT8: 지육($/kg) | GU8: 4.85 | GV8: 4.63 | GW8: 4.56 | GX8: =(GW8-GV8)/GV8 -> -0.01511879 | GY8: =(GW8-GU8)/GU8 -> -0.059793814 | HA8: 가격 | HB8: 지육($/kg) | HC8: 4.85 | HD8: 4.56 | HE8: 4.52 | HF8: =(HE8-HD8)/HD8 -> -0.0087719298 | HG8: =(HE8-HC8)/HC8 -> -0.068041237 | HI8: 가격 | HJ8: 지육($/kg) | HK8: 4.74 | HL8: 4.52 | HM8: 4.43 | HN8: =(HM8-HL8)/HL8 -> -0.019911504 | HO8: =(HM8-HK8)/HK8 -> -0.065400844 | HQ8: 가격 | HR8: 지육($/kg) | HS8: 4.7 | HT8: 4.43 | HU8: 4.45 | HV8: =(HU8-HT8)/HT8 -> 0.0045146727 | HW8: =(HU8-HS8)/HS8 -> -0.053191489 | HY8: 가격 | HZ8: 지육($/kg) | IA8: 4.7 | IB8: 4.45 | IC8: 4.45 | ID8: =(IC8-IB8)/IB8 -> 0 | IE8: =(IC8-IA8)/IA8 -> -0.053191489 | IG8: 가격 | IH8: 지육($/kg) | II8: 4.7 | IJ8: 4.45 | IK8: 4.52 | IL8: =(IK8-IJ8)/IJ8 -> 0.015730337 | IM8: =(IK8-II8)/II8 -> -0.038297872 | IO8: 가격 | IP8: 지육($/kg) | IQ8: 4.76 | IR8: 4.52 | IS8: 4.63 | IT8: =(IS8-IR8)/IR8 -> 0.024336283 | IU8: =(IS8-IQ8)/IQ8 -> -0.027310924 | IW8: 가격 | IX8: 지육($/kg) | IY8: 5.07 | IZ8: 4.63 | JA8: 4.92 | JB8: =(JA8-IZ8)/IZ8 -> 0.062634989 | JC8: =(JA8-IY8)/IY8 -> -0.029585799 | JE8: 가격 | JF8: 지육($/kg) | JG8: 5.29 | JH8: 4.92 | JI8: 5.07 | JJ8: =(JI8-JH8)/JH8 -> 0.030487805 | JK8: =(JI8-JG8)/JG8 -> -0.041587902 | JM8: 가격 | JN8: 지육($/kg) | JO8: 5.16 | JP8: 5.07 | JQ8: 5 | JR8: =(JQ8-JP8)/JP8 -> -0.013806706 | JS8: =(JQ8-JO8)/JO8 -> -0.031007752 | JU8: 가격 | JV8: 지육($/kg) | JW8: 5.07 | JX8: 5 | JY8: 4.89 | JZ8: =(JY8-JX8)/JX8 -> -0.022 | KA8: =(JY8-JW8)/JW8 -> -0.035502959 | KC8: 가격 | KD8: 지육($/kg) | KE8: 4.92 | KF8: 4.89 | KG8: 4.76 | KH8: =(KG8-KF8)/KF8 -> -0.026584867 | KI8: =(KG8-KE8)/KE8 -> -0.032520325 | KK8: 가격 | KL8: 지육($/kg) | KM8: 4.83 | KN8: 4.76 | KO8: 4.78 | KP8: =(KO8-KN8)/KN8 -> 0.0042016807 | KQ8: =(KO8-KM8)/KM8 -> -0.010351967 | KS8: 가격 | KT8: 지육($/kg) | KU8: 4.74 | KV8: 4.78 | KW8: 4.81 | KX8: =(KW8-KV8)/KV8 -> 0.0062761506 | KY8: =(KW8-KU8)/KU8 -> 0.014767932 | LA8: 가격 | LB8: 지육($/kg) | LC8: 4.7 | LD8: 4.81 | LE8: 4.76 | LF8: =(LE8-LD8)/LD8 -> -0.01039501 | LG8: =(LE8-LC8)/LC8 -> 0.012765957 | LI8: 가격 | LJ8: 지육($/kg) | LK8: 4.72 | LL8: 4.76 | LM8: 4.67 | LN8: =(LM8-LL8)/LL8 -> -0.018907563 | LO8: =(LM8-LK8)/LK8 -> -0.01059322 | LQ8: 가격 | LR8: 지육($/kg) | LS8: 4.81 | LT8: 4.67 | LU8: 4.61 | LV8: =(LU8-LT8)/LT8 -> -0.012847966 | LW8: =(LU8-LS8)/LS8 -> -0.041580042 | LY8: 가격 | LZ8: 지육($/kg) | MA8: 4.92 | MB8: 4.61 | MC8: 4.56 | MD8: =(MC8-MB8)/MB8 -> -0.010845987 | ME8: =(MC8-MA8)/MA8 -> -0.073170732 | MG8: 가격 | MH8: 지육($/kg) | MI8: 5.09 | MJ8: 4.56 | MK8: 4.65 | ML8: =(MK8-MJ8)/MJ8 -> 0.019736842 | MM8: =(MK8-MI8)/MI8 -> -0.086444008 | MO8: 가격 | MP8: 지육($/kg) | MQ8: 5.22 | MR8: 4.65 | MS8: 4.92 | MT8: =(MS8-MR8)/MR8 -> 0.058064516 | MU8: =(MS8-MQ8)/MQ8 -> -0.057471264 | MW8: 가격 | MX8: 지육($/kg) | MY8: 5.31 | MZ8: 4.92 | NA8: 5.18 | NB8: =(NA8-MZ8)/MZ8 -> 0.052845528 | NC8: =(NA8-MY8)/MY8 -> -0.024482109 | NE8: 가격 | NF8: 지육($/kg) | NG8: 5.22 | NH8: 5.18 | NI8: 5.36 | NJ8: =(NI8-NH8)/NH8 -> 0.034749035 | NK8: =(NI8-NG8)/NG8 -> 0.026819923 | NM8: 가격 | NN8: 지육($/kg) | NO8: 5.11 | NP8: 5.36 | NQ8: 5.29 | NR8: =(NQ8-NP8)/NP8 -> -0.013059701 | NS8: =(NQ8-NO8)/NO8 -> 0.035225049 | NU8: 가격 | NV8: 지육($/kg) | NW8: 5.03 | NX8: 5.29 | NY8: 4.87 | NZ8: =(NY8-NX8)/NX8 -> -0.079395085 | OA8: =(NY8-NW8)/NW8 -> -0.031809145 | OC8: 가격 | OD8: 지육($/kg) | OE8: 4.83 | OF8: 4.87 | OG8: 4.61 | OH8: =(OG8-OF8)/OF8 -> -0.05338809 | OI8: =(OG8-OE8)/OE8 -> -0.045548654 | OK8: 가격 | OL8: 지육($/kg) | OM8: 4.67 | ON8: 4.61 | OO8: 4.63 | OP8: =(OO8-ON8)/ON8 -> 0.0043383948 | OQ8: =(OO8-OM8)/OM8 -> -0.0085653105
FF9: 지육($/lb) | FG9: 2.21 | FH9: 4.05 | FI9: 3.74 | FJ9: =(FI9-FH9)/FH9 -> -0.07654321 | FK9: =(FI9-FG9)/FG9 -> 0.69230769 | FN9: 지육(원/kg) | FO9: 5791 | FP9: 10035 | FQ9: 7837 | FR9: =(FQ9-FP9)/FP9 -> -0.21903338 | FS9: =(FQ9-FO9)/FO9 -> 0.35330686 | FV9: 지육(원/kg) | FW9: 5300 | FX9: 7837 | FY9: 6299 | FZ9: =(FY9-FX9)/FX9 -> -0.19624856 | GA9: =(FY9-FW9)/FW9 -> 0.18849057 | GD9: 지육(원/kg) | GE9: 5758 | GF9: 6299 | GG9: 5850 | GH9: =(GG9-GF9)/GF9 -> -0.071281156 | GI9: =(GG9-GE9)/GE9 -> 0.01597777 | GL9: 지육(원/kg) | GM9: 5635 | GN9: 5850 | GO9: 5572 | GP9: =(GO9-GN9)/GN9 -> -0.047521368 | GQ9: =(GO9-GM9)/GM9 -> -0.011180124 | GT9: 지육(원/kg) | GU9: 5677 | GV9: 5572 | GW9: 5453 | GX9: =(GW9-GV9)/GV9 -> -0.021356784 | GY9: =(GW9-GU9)/GU9 -> -0.03945746 | HB9: 지육(원/kg) | HC9: 5730 | HD9: 5453 | HE9: 5428 | HF9: =(HE9-HD9)/HD9 -> -0.0045846323 | HG9: =(HE9-HC9)/HC9 -> -0.052705061 | HJ9: 지육(원/kg) | HK9: 5598 | HL9: 5428 | HM9: 5304 | HN9: =(HM9-HL9)/HL9 -> -0.02284451 | HO9: =(HM9-HK9)/HK9 -> -0.052518757 | HR9: 지육(원/kg) | HS9: 5534 | HT9: 5304 | HU9: 5321 | HV9: =(HU9-HT9)/HT9 -> 0.0032051282 | HW9: =(HU9-HS9)/HS9 -> -0.038489339 | HZ9: 지육(원/kg) | IA9: 5555 | IB9: 5321 | IC9: 5291 | ID9: =(IC9-IB9)/IB9 -> -0.005638038 | IE9: =(IC9-IA9)/IA9 -> -0.047524752 | IH9: 지육(원/kg) | II9: 5708 | IJ9: 5291 | IK9: 5353 | IL9: =(IK9-IJ9)/IJ9 -> 0.011718012 | IM9: =(IK9-II9)/II9 -> -0.062193413 | IP9: 지육(원/kg) | IQ9: 5786 | IR9: 5353 | IS9: 5468 | IT9: =(IS9-IR9)/IR9 -> 0.02148328 | IU9: =(IS9-IQ9)/IQ9 -> -0.054960249 | IX9: 지육(원/kg) | IY9: 6103 | IZ9: 5468 | JA9: 5836 | JB9: =(JA9-IZ9)/IZ9 -> 0.067300658 | JC9: =(JA9-IY9)/IY9 -> -0.043748976 | JF9: 지육(원/kg) | JG9: 6426 | JH9: 5836 | JI9: 6019 | JJ9: =(JI9-JH9)/JH9 -> 0.031357094 | JK9: =(JI9-JG9)/JG9 -> -0.063336446 | JN9: 지육(원/kg) | JO9: 6227 | JP9: 6019 | JQ9: 5943 | JR9: =(JQ9-JP9)/JP9 -> -0.012626682 | JS9: =(JQ9-JO9)/JO9 -> -0.045607837 | JV9: 지육(원/kg) | JW9: 6057 | JX9: 5943 | JY9: 5743 | JZ9: =(JY9-JX9)/JX9 -> -0.033653037 | KA9: =(JY9-JW9)/JW9 -> -0.051840845 | KD9: 지육(원/kg) | KE9: 5860 | KF9: 5743 | KG9: 5547 | KH9: =(KG9-KF9)/KF9 -> -0.034128504 | KI9: =(KG9-KE9)/KE9 -> -0.053412969 | KL9: 지육(원/kg) | KM9: 5796 | KN9: 5547 | KO9: 5593 | KP9: =(KO9-KN9)/KN9 -> 0.0082927709 | KQ9: =(KO9-KM9)/KM9 -> -0.035024155 | KT9: 지육(원/kg) | KU9: 5721 | KV9: 5593 | KW9: 5583 | KX9: =(KW9-KV9)/KV9 -> -0.0017879492 | KY9: =(KW9-KU9)/KU9 -> -0.024121657 | LB9: 지육(원/kg) | LC9: 5619 | LD9: 5583 | LE9: 5460 | LF9: =(LE9-LD9)/LD9 -> -0.022031166 | LG9: =(LE9-LC9)/LC9 -> -0.02829685 | LJ9: 지육(원/kg) | LK9: 5612 | LL9: 5460 | LM9: 5298 | LN9: =(LM9-LL9)/LL9 -> -0.02967033 | LO9: =(LM9-LK9)/LK9 -> -0.055951532 | LR9: 지육(원/kg) | LS9: 5638 | LT9: 5298 | LU9: 5223 | LV9: =(LU9-LT9)/LT9 -> -0.014156285 | LW9: =(LU9-LS9)/LS9 -> -0.073607662 | LZ9: 지육(원/kg) | MA9: 5735 | MB9: 5223 | MC9: 5202 | MD9: =(MC9-MB9)/MB9 -> -0.0040206778 | ME9: =(MC9-MA9)/MA9 -> -0.092938099 | MH9: 지육(원/kg) | MI9: 5900 | MJ9: 5202 | MK9: 5177 | ML9: =(MK9-MJ9)/MJ9 -> -0.0048058439 | MM9: =(MK9-MI9)/MI9 -> -0.12254237 | MP9: 지육(원/kg) | MQ9: 6111 | MR9: 5177 | MS9: 5425 | MT9: =(MS9-MR9)/MR9 -> 0.047904192 | MU9: =(MS9-MQ9)/MQ9 -> -0.11225659 | MX9: 지육(원/kg) | MY9: 6219 | MZ9: 5425 | NA9: 5735 | NB9: =(NA9-MZ9)/MZ9 -> 0.057142857 | NC9: =(NA9-MY9)/MY9 -> -0.077826017 | NF9: 지육(원/kg) | NG9: 6152 | NH9: 5735 | NI9: 5909 | NJ9: =(NI9-NH9)/NH9 -> 0.030340017 | NK9: =(NI9-NG9)/NG9 -> -0.03949935 | NN9: 지육(원/kg) | NO9: 6102 | NP9: 5909 | NQ9: 5741 | NR9: =(NQ9-NP9)/NP9 -> -0.028431207 | NS9: =(NQ9-NO9)/NO9 -> -0.059160931 | NV9: 지육(원/kg) | NW9: 6005 | NX9: 5741 | NY9: 5316 | NZ9: =(NY9-NX9)/NX9 -> -0.074028915 | OA9: =(NY9-NW9)/NW9 -> -0.11473772 | OD9: 지육(원/kg) | OE9: 5642 | OF9: 5316 | OG9: 5109 | OH9: =(OG9-OF9)/OF9 -> -0.038939052 | OI9: =(OG9-OE9)/OE9 -> -0.094470046 | OL9: 지육(원/kg) | OM9: 5440 | ON9: 5109 | OO9: 5035 | OP9: =(OO9-ON9)/ON9 -> -0.014484243 | OQ9: =(OO9-OM9)/OM9 -> -0.074448529
FE11: 쇠고기/호주 | FM11: 쇠고기/호주 | FU11: 쇠고기/호주 | GC11: 쇠고기/호주 | GK11: 쇠고기/호주 | GS11: 쇠고기/호주 | HA11: 쇠고기/호주 | HI11: 쇠고기/호주 | HQ11: 쇠고기/호주 | HY11: 쇠고기/호주 | IG11: 쇠고기/호주 | IO11: 쇠고기/호주 | IW11: 쇠고기/호주 | JE11: 쇠고기/호주 | JM11: 쇠고기/호주 | JU11: 쇠고기/호주 | KC11: 쇠고기/호주 | KK11: 쇠고기/호주 | KS11: 쇠고기/호주 | LA11: 쇠고기/호주 | LI11: 쇠고기/호주 | LQ11: 쇠고기/호주 | LY11: 쇠고기/호주 | MG11: 쇠고기/호주 | MO11: 쇠고기/호주 | MW11: 쇠고기/호주 | NE11: 쇠고기/호주 | NM11: 쇠고기/호주 | NU11: 쇠고기/호주 | OC11: 쇠고기/호주 | OK11: 쇠고기/호주
FE12: 구분 | FG12: 2019년 | FH12: 2020년 | FJ12: 전주 | FK12: 전년 | FM12: 구분 | FO12: 2019년 | FP12: 2020년 | FR12: 전주 | FS12: 전년 | FU12: 구분 | FW12: 2019년 | FX12: 2020년 | FZ12: 전주 | GA12: 전년 | GC12: 구분 | GE12: 2019년 | GF12: 2020년 | GH12: 전주 | GI12: 전년 | GK12: 구분 | GM12: 2019년 | GN12: 2020년 | GP12: 전주 | GQ12: 전년 | GS12: 구분 | GU12: 2019년 | GV12: 2020년 | GX12: 전주 | GY12: 전년 | HA12: 구분 | HC12: 2019년 | HD12: 2020년 | HF12: 전주 | HG12: 전년 | HI12: 구분 | HK12: 2019년 | HL12: 2020년 | HN12: 전주 | HO12: 전년 | HQ12: 구분 | HS12: 2019년 | HT12: 2020년 | HV12: 전주 | HW12: 전년 | HY12: 구분 | IA12: 2019년 | IB12: 2020년 | ID12: 전주 | IE12: 전년 | IG12: 구분 | II12: 2019년 | IJ12: 2020년 | IL12: 전주 | IM12: 전년 | IO12: 구분 | IQ12: 2019년 | IR12: 2020년 | IT12: 전주 | IU12: 전년 | IW12: 구분 | IY12: 2019년 | IZ12: 2020년 | JB12: 전주 | JC12: 전년 | JE12: 구분 | JG12: 2019년 | JH12: 2020년 | JJ12: 전주 | JK12: 전년 | JM12: 구분 | JO12: 2019년 | JP12: 2020년 | JR12: 전주 | JS12: 전년 | JU12: 구분 | JW12: 2019년 | JX12: 2020년 | JZ12: 전주 | KA12: 전년 | KC12: 구분 | KE12: 2019년 | KF12: 2020년 | KH12: 전주 | KI12: 전년 | KK12: 구분 | KM12: 2019년 | KN12: 2020년 | KP12: 전주 | KQ12: 전년 | KS12: 구분 | KU12: 2019년 | KV12: 2020년 | KX12: 전주 | KY12: 전년 | LA12: 구분 | LC12: 2019년 | LD12: 2020년 | LF12: 전주 | LG12: 전년 | LI12: 구분 | LK12: 2019년 | LL12: 2020년 | LN12: 전주 | LO12: 전년 | LQ12: 구분 | LS12: 2019년 | LT12: 2020년 | LV12: 전주 | LW12: 전년 | LY12: 구분 | MA12: 2019년 | MB12: 2020년 | MD12: 전주 | ME12: 전년 | MG12: 구분 | MI12: 2019년 | MJ12: 2020년 | ML12: 전주 | MM12: 전년 | MO12: 구분 | MQ12: 2019년 | MR12: 2020년 | MT12: 전주 | MU12: 전년 | MW12: 구분 | MY12: 2019년 | MZ12: 2020년 | NB12: 전주 | NC12: 전년 | NE12: 구분 | NG12: 2019년 | NH12: 2020년 | NJ12: 전주 | NK12: 전년 | NM12: 구분 | NO12: 2019년 | NP12: 2020년 | NR12: 전주 | NS12: 전년 | NU12: 구분 | NW12: 2019년 | NX12: 2020년 | NZ12: 전주 | OA12: 전년 | OC12: 구분 | OE12: 2019년 | OF12: 2020년 | OH12: 전주 | OI12: 전년 | OK12: 구분 | OM12: 2019년 | ON12: 2020년 | OP12: 전주 | OQ12: 전년
FG13: 5월4주 | FH13: 5월3주 | FI13: 5월4주 | FJ13: 대비 | FK13: 대비 | FO13: 6월1주 | FP13: 3월3주 | FQ13: 6월1주 | FR13: 대비 | FS13: 대비 | FW13: 6월2주 | FX13: 6월1주 | FY13: 6월2주 | FZ13: 대비 | GA13: 대비 | GE13: 6월3주 | GF13: 6월2주 | GG13: 6월3주 | GH13: 대비 | GI13: 대비 | GM13: 6월4주 | GN13: 6월3주 | GO13: 6월4주 | GP13: 대비 | GQ13: 대비 | GU13: 7월1주 | GV13: 6월4주 | GW13: 7월1주 | GX13: 대비 | GY13: 대비 | HC13: 7월2주 | HD13: 7월1주 | HE13: 7월2주 | HF13: 대비 | HG13: 대비 | HK13: 7월3주 | HL13: 7월2주 | HM13: 7월3주 | HN13: 대비 | HO13: 대비 | HS13: 7월 4주 | HT13: 7월3주 | HU13: 7월 4주 | HV13: 대비 | HW13: 대비 | IA13: 7월 5주 | IB13: 7월 4주 | IC13: 7월 5주 | ID13: 대비 | IE13: 대비 | II13: 8월 1주 | IJ13: 7월 5주 | IK13: 8월 1주 | IL13: 대비 | IM13: 대비 | IQ13: 8월 2주 | IR13: 8월 1주 | IS13: 8월 2주 | IT13: 대비 | IU13: 대비 | IY13: 8월 3주 | IZ13: 8월 2주 | JA13: 8월 3주 | JB13: 대비 | JC13: 대비 | JG13: 8월 4주 | JH13: 8월 3주 | JI13: 8월 4주 | JJ13: 대비 | JK13: 대비 | JO13: 9월 1주 | JP13: 8월 4주 | JQ13: 9월 1주 | JR13: 대비 | JS13: 대비 | JW13: 9월 2주 | JX13: 9월 1주 | JY13: 9월 2주 | JZ13: 대비 | KA13: 대비 | KE13: 9월 3주 | KF13: 9월 2주 | KG13: 9월 3주 | KH13: 대비 | KI13: 대비 | KM13: 9월 4주 | KN13: 9월 3주 | KO13: 9월 4주 | KP13: 대비 | KQ13: 대비 | KU13: 9월 5주 | KV13: 9월 4주 | KW13: 9월 5주 | KX13: 대비 | KY13: 대비 | LC13: 10월1주 | LD13: 9월 5주 | LE13: 10월1주 | LF13: 대비 | LG13: 대비 | LK13: 10월2주 | LL13: 10월1주 | LM13: 10월2주 | LN13: 대비 | LO13: 대비 | LS13: 10월3주 | LT13: 10월2주 | LU13: 10월3주 | LV13: 대비 | LW13: 대비 | MA13: 10월4주 | MB13: 10월3주 | MC13: 10월4주 | MD13: 대비 | ME13: 대비 | MI13: 11월1주 | MJ13: 10월4주 | MK13: 11월1주 | ML13: 대비 | MM13: 대비 | MQ13: 11월2주 | MR13: 11월1주 | MS13: 11월2주 | MT13: 대비 | MU13: 대비 | MY13: 11월3주 | MZ13: 11월2주 | NA13: 11월3주 | NB13: 대비 | NC13: 대비 | NG13: 11월4주 | NH13: 11월3주 | NI13: 11월4주 | NJ13: 대비 | NK13: 대비 | NO13: 12월1주 | NP13: 11월4주 | NQ13: 12월1주 | NR13: 대비 | NS13: 대비 | NW13: 12월2주 | NX13: 12월1주 | NY13: 12월2주 | NZ13: 대비 | OA13: 대비 | OE13: 12월3주 | OF13: 12월2주 | OG13: 12월3주 | OH13: 대비 | OI13: 대비 | OM13: 12월4주 | ON13: 12월3주 | OO13: 12월4주 | OP13: 대비 | OQ13: 대비
FE14: 수급 | FF14: 도축(천두) | FG14: 158 | FH14: 126 | FI14: 130 | FJ14: =(FI14-FH14)/FH14 -> 0.031746032 | FK14: =(FI14-FG14)/FG14 -> -0.17721519 | FM14: 수급 | FN14: 도축(천두) | FO14: 154 | FP14: 130 | FQ14: 120 | FR14: =(FQ14-FP14)/FP14 -> -0.076923077 | FS14: =(FQ14-FO14)/FO14 -> -0.22077922 | FU14: 수급 | FV14: 도축(천두) | FW14: 142 | FX14: 120 | FY14: 121 | FZ14: =(FY14-FX14)/FX14 -> 0.0083333333 | GA14: =(FY14-FW14)/FW14 -> -0.14788732 | GC14: 수급 | GD14: 도축(천두) | GE14: 154 | GF14: 121 | GG14: 123 | GH14: =(GG14-GF14)/GF14 -> 0.016528926 | GI14: =(GG14-GE14)/GE14 -> -0.2012987 | GK14: 수급 | GL14: 도축(천두) | GM14: 160 | GN14: 123 | GO14: 121 | GP14: =(GO14-GN14)/GN14 -> -0.016260163 | GQ14: =(GO14-GM14)/GM14 -> -0.24375 | GS14: 수급 | GT14: 도축(천두) | GU14: 153 | GV14: 121 | GW14: 127 | GX14: =(GW14-GV14)/GV14 -> 0.049586777 | GY14: =(GW14-GU14)/GU14 -> -0.16993464 | HA14: 수급 | HB14: 도축(천두) | HC14: 151 | HD14: 127 | HE14: 122 | HF14: =(HE14-HD14)/HD14 -> -0.039370079 | HG14: =(HE14-HC14)/HC14 -> -0.19205298 | HI14: 수급 | HJ14: 도축(천두) | HK14: 147 | HL14: 122 | HM14: 118 | HN14: =(HM14-HL14)/HL14 -> -0.032786885 | HO14: =(HM14-HK14)/HK14 -> -0.19727891 | HQ14: 수급 | HR14: 도축(천두) | HS14: 149 | HT14: 118 | HU14: 112 | HV14: =(HU14-HT14)/HT14 -> -0.050847458 | HW14: =(HU14-HS14)/HS14 -> -0.24832215 | HY14: 수급 | HZ14: 도축(천두) | IA14: 146 | IB14: 112 | IC14: 115 | ID14: =(IC14-IB14)/IB14 -> 0.026785714 | IE14: =(IC14-IA14)/IA14 -> -0.21232877 | IG14: 수급 | IH14: 도축(천두) | II14: 148 | IJ14: 115 | IK14: 118 | IL14: =(IK14-IJ14)/IJ14 -> 0.026086957 | IM14: =(IK14-II14)/II14 -> -0.2027027 | IO14: 수급 | IP14: 도축(천두) | IQ14: 140 | IR14: 118 | IS14: 98 | IT14: =(IS14-IR14)/IR14 -> -0.16949153 | IU14: =(IS14-IQ14)/IQ14 -> -0.3 | IW14: 수급 | IX14: 도축(천두) | IY14: 151 | IZ14: 98 | JA14: 107 | JB14: =(JA14-IZ14)/IZ14 -> 0.091836735 | JC14: =(JA14-IY14)/IY14 -> -0.29139073 | JE14: 수급 | JF14: 도축(천두) | JG14: 152 | JH14: 107 | JI14: 102 | JJ14: =(JI14-JH14)/JH14 -> -0.046728972 | JK14: =(JI14-JG14)/JG14 -> -0.32894737 | JM14: 수급 | JN14: 도축(천두) | JO14: 147 | JP14: 102 | JQ14: 106 | JR14: =(JQ14-JP14)/JP14 -> 0.039215686 | JS14: =(JQ14-JO14)/JO14 -> -0.27891156 | JU14: 수급 | JV14: 도축(천두) | JW14: 145 | JX14: 106 | JY14: 112 | JZ14: =(JY14-JX14)/JX14 -> 0.056603774 | KA14: =(JY14-JW14)/JW14 -> -0.22758621 | KC14: 수급 | KD14: 도축(천두) | KE14: 153 | KF14: 112 | KG14: 101 | KH14: =(KG14-KF14)/KF14 -> -0.098214286 | KI14: =(KG14-KE14)/KE14 -> -0.33986928 | KK14: 수급 | KL14: 도축(천두) | KM14: 148 | KN14: 101 | KO14: 108 | KP14: =(KO14-KN14)/KN14 -> 0.069306931 | KQ14: =(KO14-KM14)/KM14 -> -0.27027027 | KS14: 수급 | KT14: 도축(천두) | KU14: 149 | KV14: 108 | KW14: 103 | KX14: =(KW14-KV14)/KV14 -> -0.046296296 | KY14: =(KW14-KU14)/KU14 -> -0.30872483 | LA14: 수급 | LB14: 도축(천두) | LC14: 137 | LD14: 103 | LE14: 89 | LF14: =(LE14-LD14)/LD14 -> -0.13592233 | LG14: =(LE14-LC14)/LC14 -> -0.35036496 | LI14: 수급 | LJ14: 도축(천두) | LK14: 151 | LL14: 89 | LM14: 109 | LN14: =(LM14-LL14)/LL14 -> 0.2247191 | LO14: =(LM14-LK14)/LK14 -> -0.2781457 | LQ14: 수급 | LR14: 도축(천두) | LS14: 154 | LT14: 109 | LU14: 109 | LV14: =(LU14-LT14)/LT14 -> 0 | LW14: =(LU14-LS14)/LS14 -> -0.29220779 | LY14: 수급 | LZ14: 도축(천두) | MA14: 154 | MB14: 109 | MC14: 117 | MD14: =(MC14-MB14)/MB14 -> 0.073394495 | ME14: =(MC14-MA14)/MA14 -> -0.24025974 | MG14: 수급 | MH14: 도축(천두) | MI14: 152 | MJ14: 117 | MK14: 102 | ML14: =(MK14-MJ14)/MJ14 -> -0.12820513 | MM14: =(MK14-MI14)/MI14 -> -0.32894737 | MO14: 수급 | MP14: 도축(천두) | MQ14: 157 | MR14: 102 | MS14: 110 | MT14: =(MS14-MR14)/MR14 -> 0.078431373 | MU14: =(MS14-MQ14)/MQ14 -> -0.29936306 | MW14: 수급 | MX14: 도축(천두) | MY14: 158 | MZ14: 110 | NA14: 104 | NB14: =(NA14-MZ14)/MZ14 -> -0.054545455 | NC14: =(NA14-MY14)/MY14 -> -0.34177215 | NE14: 수급 | NF14: 도축(천두) | NG14: 157 | NH14: 104 | NI14: 110 | NJ14: =(NI14-NH14)/NH14 -> 0.057692308 | NK14: =(NI14-NG14)/NG14 -> -0.29936306 | NM14: 수급 | NN14: 도축(천두) | NO14: 160 | NP14: 110 | NQ14: 115 | NR14: =(NQ14-NP14)/NP14 -> 0.045454545 | NS14: =(NQ14-NO14)/NO14 -> -0.28125 | NU14: 수급 | NV14: 도축(천두) | NW14: 165 | NX14: 115 | NY14: 112 | NZ14: =(NY14-NX14)/NX14 -> -0.026086957 | OA14: =(NY14-NW14)/NW14 -> -0.32121212 | OC14: 수급 | OD14: 도축(천두) | OF14: 112 | OH14: =(OG14-OF14)/OF14 -> -1 | OI14: =(OG14-OE14)/OE14 -> #DIV/0! | OK14: 수급 | OL14: 도축(천두) | OM14: - | ON14: - | OP14: =(OO14-ON14)/ON14 -> #VALUE! | OQ14: =(OO14-OM14)/OM14 -> #VALUE!
FF15: 수출(천톤) | FJ15: =(FI15-FH15)/FH15 -> #DIV/0! | FK15: =(FI15-FG15)/FG15 -> #DIV/0! | FN15: 수출(천톤) | FR15: =(FQ15-FP15)/FP15 -> #DIV/0! | FS15: =(FQ15-FO15)/FO15 -> #DIV/0! | FV15: 수출(천톤) | FZ15: =(FY15-FX15)/FX15 -> #DIV/0! | GA15: =(FY15-FW15)/FW15 -> #DIV/0! | GD15: 수출(천톤) | GH15: =(GG15-GF15)/GF15 -> #DIV/0! | GI15: =(GG15-GE15)/GE15 -> #DIV/0! | GL15: 수출(천톤) | GP15: =(GO15-GN15)/GN15 -> #DIV/0! | GQ15: =(GO15-GM15)/GM15 -> #DIV/0! | GT15: 수출(천톤) | GX15: =(GW15-GV15)/GV15 -> #DIV/0! | GY15: =(GW15-GU15)/GU15 -> #DIV/0! | HB15: 수출(천톤) | HF15: =(HE15-HD15)/HD15 -> #DIV/0! | HG15: =(HE15-HC15)/HC15 -> #DIV/0! | HJ15: 수출(천톤) | HN15: =(HM15-HL15)/HL15 -> #DIV/0! | HO15: =(HM15-HK15)/HK15 -> #DIV/0! | HR15: 수출(천톤) | HV15: =(HU15-HT15)/HT15 -> #DIV/0! | HW15: =(HU15-HS15)/HS15 -> #DIV/0! | HZ15: 수출(천톤) | ID15: =(IC15-IB15)/IB15 -> #DIV/0! | IE15: =(IC15-IA15)/IA15 -> #DIV/0! | IH15: 수출(천톤) | IL15: =(IK15-IJ15)/IJ15 -> #DIV/0! | IM15: =(IK15-II15)/II15 -> #DIV/0! | IP15: 수출(천톤) | IT15: =(IS15-IR15)/IR15 -> #DIV/0! | IU15: =(IS15-IQ15)/IQ15 -> #DIV/0! | IX15: 수출(천톤) | JB15: =(JA15-IZ15)/IZ15 -> #DIV/0! | JC15: =(JA15-IY15)/IY15 -> #DIV/0! | JF15: 수출(천톤) | JJ15: =(JI15-JH15)/JH15 -> #DIV/0! | JK15: =(JI15-JG15)/JG15 -> #DIV/0! | JN15: 수출(천톤) | JR15: =(JQ15-JP15)/JP15 -> #DIV/0! | JS15: =(JQ15-JO15)/JO15 -> #DIV/0! | JV15: 수출(천톤) | JZ15: =(JY15-JX15)/JX15 -> #DIV/0! | KA15: =(JY15-JW15)/JW15 -> #DIV/0! | KD15: 수출(천톤) | KH15: =(KG15-KF15)/KF15 -> #DIV/0! | KI15: =(KG15-KE15)/KE15 -> #DIV/0! | KL15: 수출(천톤) | KP15: =(KO15-KN15)/KN15 -> #DIV/0! | KQ15: =(KO15-KM15)/KM15 -> #DIV/0! | KT15: 수출(천톤) | KX15: =(KW15-KV15)/KV15 -> #DIV/0! | KY15: =(KW15-KU15)/KU15 -> #DIV/0! | LB15: 수출(천톤) | LF15: =(LE15-LD15)/LD15 -> #DIV/0! | LG15: =(LE15-LC15)/LC15 -> #DIV/0! | LJ15: 수출(천톤) | LN15: =(LM15-LL15)/LL15 -> #DIV/0! | LO15: =(LM15-LK15)/LK15 -> #DIV/0! | LR15: 수출(천톤) | LV15: =(LU15-LT15)/LT15 -> #DIV/0! | LW15: =(LU15-LS15)/LS15 -> #DIV/0! | LZ15: 수출(천톤) | MD15: =(MC15-MB15)/MB15 -> #DIV/0! | ME15: =(MC15-MA15)/MA15 -> #DIV/0! | MH15: 수출(천톤) | ML15: =(MK15-MJ15)/MJ15 -> #DIV/0! | MM15: =(MK15-MI15)/MI15 -> #DIV/0! | MP15: 수출(천톤) | MT15: =(MS15-MR15)/MR15 -> #DIV/0! | MU15: =(MS15-MQ15)/MQ15 -> #DIV/0! | MX15: 수출(천톤) | NB15: =(NA15-MZ15)/MZ15 -> #DIV/0! | NC15: =(NA15-MY15)/MY15 -> #DIV/0! | NF15: 수출(천톤) | NJ15: =(NI15-NH15)/NH15 -> #DIV/0! | NK15: =(NI15-NG15)/NG15 -> #DIV/0! | NN15: 수출(천톤) | NR15: =(NQ15-NP15)/NP15 -> #DIV/0! | NS15: =(NQ15-NO15)/NO15 -> #DIV/0! | NV15: 수출(천톤) | NZ15: =(NY15-NX15)/NX15 -> #DIV/0! | OA15: =(NY15-NW15)/NW15 -> #DIV/0! | OD15: 수출(천톤) | OH15: =(OG15-OF15)/OF15 -> #DIV/0! | OI15: =(OG15-OE15)/OE15 -> #DIV/0! | OL15: 수출(천톤) | OP15: =(OO15-ON15)/ON15 -> #DIV/0! | OQ15: =(OO15-OM15)/OM15 -> #DIV/0!
FE16: 가격 | FF16: 생우(A$/lb) | FG16: 2.87 | FI16: 3.51 | FJ16: =(FI16-FH16)/FH16 -> #DIV/0! | FK16: =(FI16-FG16)/FG16 -> 0.22299652 | FM16: 가격 | FN16: 지육(A$/kg) | FR16: =(FQ16-FP16)/FP16 -> #DIV/0! | FS16: =(FQ16-FO16)/FO16 -> #DIV/0! | FU16: 가격 | FV16: 지육(A$/kg) | FZ16: =(FY16-FX16)/FX16 -> #DIV/0! | GA16: =(FY16-FW16)/FW16 -> #DIV/0! | GC16: 가격 | GD16: 지육(A$/kg) | GE16: 492.25 | GF16: 757 | GG16: 770.25 | GH16: =(GG16-GF16)/GF16 -> 0.017503303 | GI16: =(GG16-GE16)/GE16 -> 0.56475368 | GK16: 가격 | GL16: 지육(A$/kg) | GM16: 4.89 | GN16: 7.7 | GO16: 7.54 | GP16: =(GO16-GN16)/GN16 -> -0.020779221 | GQ16: =(GO16-GM16)/GM16 -> 0.54192229 | GS16: 가격 | GT16: 지육(A$/kg) | GU16: 4.92 | GV16: 7.54 | GW16: 7.64 | GX16: =(GW16-GV16)/GV16 -> 0.013262599 | GY16: =(GW16-GU16)/GU16 -> 0.55284553 | HA16: 가격 | HB16: 지육(A$/kg) | HC16: 5.16 | HD16: 7.64 | HE16: 7.51 | HF16: =(HE16-HD16)/HD16 -> -0.017015707 | HG16: =(HE16-HC16)/HC16 -> 0.45542636 | HI16: 가격 | HJ16: 지육(A$/kg) | HK16: 5.2 | HL16: 7.51 | HM16: 7.43 | HN16: =(HM16-HL16)/HL16 -> -0.010652463 | HO16: =(HM16-HK16)/HK16 -> 0.42884615 | HQ16: 가격 | HR16: 지육(A$/kg) | HS16: 5.32 | HT16: 7.43 | HU16: 7.53 | HV16: =(HU16-HT16)/HT16 -> 0.01345895 | HW16: =(HU16-HS16)/HS16 -> 0.41541353 | HY16: 가격 | HZ16: 지육(A$/kg) | IA16: 5.33 | IB16: 7.53 | IC16: 7.52 | ID16: =(IC16-IB16)/IB16 -> -0.0013280212 | IE16: =(IC16-IA16)/IA16 -> 0.4108818 | IG16: 가격 | IH16: 지육(A$/kg) | II16: 5.33 | IJ16: 7.52 | IK16: 7.61 | IL16: =(IK16-IJ16)/IJ16 -> 0.011968085 | IM16: =(IK16-II16)/II16 -> 0.42776735 | IO16: 가격 | IP16: 지육(A$/kg) | IQ16: 5.28 | IR16: 7.61 | IS16: 7.63 | IT16: =(IS16-IR16)/IR16 -> 0.0026281209 | IU16: =(IS16-IQ16)/IQ16 -> 0.44507576 | IW16: 가격 | IX16: 지육(A$/kg) | IY16: 5.08 | IZ16: 7.63 | JA16: 7.78 | JB16: =(JA16-IZ16)/IZ16 -> 0.01965924 | JC16: =(JA16-IY16)/IY16 -> 0.53149606 | JE16: 가격 | JF16: 지육(A$/kg) | JG16: 5.04 | JH16: 7.78 | JI16: 7.86 | JJ16: =(JI16-JH16)/JH16 -> 0.010282776 | JK16: =(JI16-JG16)/JG16 -> 0.55952381 | JM16: 가격 | JN16: 지육(A$/kg) | JO16: 5 | JP16: 7.86 | JQ16: 7.78 | JR16: =(JQ16-JP16)/JP16 -> -0.010178117 | JS16: =(JQ16-JO16)/JO16 -> 0.556 | JU16: 가격 | JV16: 지육(A$/kg) | JW16: 4.77 | JX16: 7.78 | JY16: 7.62 | JZ16: =(JY16-JX16)/JX16 -> -0.020565553 | KA16: =(JY16-JW16)/JW16 -> 0.59748428 | KC16: 가격 | KD16: 지육(A$/kg) | KE16: 4.69 | KF16: 7.62 | KG16: 7.64 | KH16: =(KG16-KF16)/KF16 -> 0.0026246719 | KI16: =(KG16-KE16)/KE16 -> 0.62899787 | KK16: 가격 | KL16: 지육(A$/kg) | KM16: 4.88 | KN16: 7.64 | KO16: 7.74 | KP16: =(KO16-KN16)/KN16 -> 0.013089005 | KQ16: =(KO16-KM16)/KM16 -> 0.58606557 | KS16: 가격 | KT16: 지육(A$/kg) | KU16: 4.9 | KV16: 7.74 | KW16: 7.76 | KX16: =(KW16-KV16)/KV16 -> 0.0025839793 | KY16: =(KW16-KU16)/KU16 -> 0.58367347 | LA16: 가격 | LB16: 지육(A$/kg) | LC16: 4.86 | LD16: 7.76 | LE16: 7.93 | LF16: =(LE16-LD16)/LD16 -> 0.021907216 | LG16: =(LE16-LC16)/LC16 -> 0.63168724 | LI16: 가격 | LJ16: 지육(A$/kg) | LK16: 5.03 | LL16: 7.93 | LM16: 7.89 | LN16: =(LM16-LL16)/LL16 -> -0.0050441362 | LO16: =(LM16-LK16)/LK16 -> 0.56858847 | LQ16: 가격 | LR16: 지육(A$/kg) | LS16: 5.01 | LT16: 7.89 | LU16: 8.01 | LV16: =(LU16-LT16)/LT16 -> 0.015209125 | LW16: =(LU16-LS16)/LS16 -> 0.5988024 | LY16: 가격 | LZ16: 지육(A$/kg) | MA16: 5.11 | MB16: 8.01 | MC16: 8.19 | MD16: =(MC16-MB16)/MB16 -> 0.02247191 | ME16: =(MC16-MA16)/MA16 -> 0.60273973 | MG16: 가격 | MH16: 지육(A$/kg) | MI16: 5.22 | MJ16: 8.19 | MK16: 8.27 | ML16: =(MK16-MJ16)/MJ16 -> 0.0097680098 | MM16: =(MK16-MI16)/MI16 -> 0.58429119 | MO16: 가격 | MP16: 지육(A$/kg) | MQ16: 5.17 | MR16: 8.27 | MS16: 8.24 | MT16: =(MS16-MR16)/MR16 -> -0.0036275695 | MU16: =(MS16-MQ16)/MQ16 -> 0.59381044 | MW16: 가격 | MX16: 지육(A$/kg) | MY16: 5.13 | MZ16: 8.24 | NA16: 8.27 | NB16: =(NA16-MZ16)/MZ16 -> 0.0036407767 | NC16: =(NA16-MY16)/MY16 -> 0.61208577 | NE16: 가격 | NF16: 지육(A$/kg) | NG16: 4.99 | NH16: 8.27 | NI16: 8.05 | NJ16: =(NI16-NH16)/NH16 -> -0.026602177 | NK16: =(NI16-NG16)/NG16 -> 0.61322645 | NM16: 가격 | NN16: 지육(A$/kg) | NO16: 4.99 | NP16: 8.05 | NQ16: 7.89 | NR16: =(NQ16-NP16)/NP16 -> -0.019875776 | NS16: =(NQ16-NO16)/NO16 -> 0.58116232 | NU16: 가격 | NV16: 지육(A$/kg) | NW16: 4.96 | NX16: 7.89 | NY16: 7.92 | NZ16: =(NY16-NX16)/NX16 -> 0.0038022814 | OA16: =(NY16-NW16)/NW16 -> 0.59677419 | OC16: 가격 | OD16: 지육(A$/kg) | OE16: 4.82 | OF16: 7.92 | OG16: 8.14 | OH16: =(OG16-OF16)/OF16 -> 0.027777778 | OI16: =(OG16-OE16)/OE16 -> 0.68879668 | OK16: 가격 | OL16: 지육(A$/kg) | OM16: - | ON16: - | OP16: =(OO16-ON16)/ON16 -> #VALUE! | OQ16: =(OO16-OM16)/OM16 -> #VALUE!
FF17: 지육(A$/lb) | FG17: 5.19 | FI17: 6.5 | FJ17: =(FI17-FH17)/FH17 -> #DIV/0! | FK17: =(FI17-FG17)/FG17 -> 0.25240848 | FN17: 지육(원/kg) | FO17: 4017 | FP17: 5425 | FQ17: 6257 | FR17: =(FQ17-FP17)/FP17 -> 0.15336406 | FS17: =(FQ17-FO17)/FO17 -> 0.55763007 | FV17: 지육(원/kg) | FW17: 3878 | FX17: 6257 | FY17: 6283 | FZ17: =(FY17-FX17)/FX17 -> 0.004155346 | GA17: =(FY17-FW17)/FW17 -> 0.62016503 | GD17: 지육(원/kg) | GE17: 3957 | GF17: 6283 | GG17: 6412 | GH17: =(GG17-GF17)/GF17 -> 0.020531593 | GI17: =(GG17-GE17)/GE17 -> 0.62041951 | GL17: 지육(원/kg) | GM17: 3953 | GN17: 6412 | GO17: 6243 | GP17: =(GO17-GN17)/GN17 -> -0.026356831 | GQ17: =(GO17-GM17)/GM17 -> 0.57930686 | GT17: 지육(원/kg) | GU17: 4037 | GV17: 6243 | GW17: 6339 | GX17: =(GW17-GV17)/GV17 -> 0.015377222 | GY17: =(GW17-GU17)/GU17 -> 0.57022541 | HB17: 지육(원/kg) | HC17: 4225 | HD17: 6339 | HE17: 6260 | HF17: =(HE17-HD17)/HD17 -> -0.012462534 | HG17: =(HE17-HC17)/HC17 -> 0.4816568 | HJ17: 지육(원/kg) | HK17: 4309 | HL17: 6260 | HM17: 6244 | HN17: =(HM17-HL17)/HL17 -> -0.0025559105 | HO17: =(HM17-HK17)/HK17 -> 0.44906011 | HR17: 지육(원/kg) | HS17: 4376 | HT17: 6244 | HU17: 6429 | HV17: =(HU17-HT17)/HT17 -> 0.029628443 | HW17: =(HU17-HS17)/HS17 -> 0.46914991 | HZ17: 지육(원/kg) | IA17: 4336 | IB17: 6429 | IC17: 6426 | ID17: =(IC17-IB17)/IB17 -> -0.00046663556 | IE17: =(IC17-IA17)/IA17 -> 0.48201107 | IH17: 지육(원/kg) | II17: 4371 | IJ17: 6426 | IK17: 6476 | IL17: =(IK17-IJ17)/IJ17 -> 0.0077808901 | IM17: =(IK17-II17)/II17 -> 0.48158316 | IP17: 지육(원/kg) | IQ17: 4335 | IR17: 6476 | IS17: 6482 | IT17: =(IS17-IR17)/IR17 -> 0.00092649784 | IU17: =(IS17-IQ17)/IQ17 -> 0.49527105 | IX17: 지육(원/kg) | IY17: 4159 | IZ17: 6482 | JA17: 6622 | JB17: =(JA17-IZ17)/IZ17 -> 0.021598272 | JC17: =(JA17-IY17)/IY17 -> 0.59220967 | JF17: 지육(원/kg) | JG17: 4121 | JH17: 6622 | JI17: 6751 | JJ17: =(JI17-JH17)/JH17 -> 0.019480519 | JK17: =(JI17-JG17)/JG17 -> 0.63819461 | JN17: 지육(원/kg) | JO17: 4092 | JP17: 6751 | JQ17: 6758 | JR17: =(JQ17-JP17)/JP17 -> 0.0010368834 | JS17: =(JQ17-JO17)/JO17 -> 0.65151515 | JV17: 지육(원/kg) | JW17: 3915 | JX17: 6758 | JY17: 6575 | JZ17: =(JY17-JX17)/JX17 -> -0.027079017 | KA17: =(JY17-JW17)/JW17 -> 0.67943806 | KD17: 지육(원/kg) | KE17: 3801 | KF17: 6575 | KG17: 6540 | KH17: =(KG17-KF17)/KF17 -> -0.0053231939 | KI17: =(KG17-KE17)/KE17 -> 0.72059984 | KL17: 지육(원/kg) | KM17: 3960 | KN17: 6540 | KO17: 6396 | KP17: =(KO17-KN17)/KN17 -> -0.022018349 | KQ17: =(KO17-KM17)/KM17 -> 0.61515152 | KT17: 지육(원/kg) | KU17: 3949 | KV17: 6396 | KW17: 6457 | KX17: =(KW17-KV17)/KV17 -> 0.0095372108 | KY17: =(KW17-KU17)/KU17 -> 0.63509749 | LB17: 지육(원/kg) | LC17: 3932 | LD17: 6457 | LE17: 6543 | LF17: =(LE17-LD17)/LD17 -> 0.013318879 | LG17: =(LE17-LC17)/LC17 -> 0.66403866 | LJ17: 지육(원/kg) | LK17: 4056 | LL17: 6543 | LM17: 6413 | LN17: =(LM17-LL17)/LL17 -> -0.019868562 | LO17: =(LM17-LK17)/LK17 -> 0.5811144 | LR17: 지육(원/kg) | LS17: 4015 | LT17: 6413 | LU17: 6456 | LV17: =(LU17-LT17)/LT17 -> 0.0067051302 | LW17: =(LU17-LS17)/LS17 -> 0.60797011 | LZ17: 지육(원/kg) | MA17: 4119 | MB17: 6456 | MC17: 6539 | MD17: =(MC17-MB17)/MB17 -> 0.012856258 | ME17: =(MC17-MA17)/MA17 -> 0.58752124 | MH17: 지육(원/kg) | MI17: 4167 | MJ17: 6539 | MK17: 6725 | ML17: =(MK17-MJ17)/MJ17 -> 0.028444716 | MM17: =(MK17-MI17)/MI17 -> 0.61387089 | MP17: 지육(원/kg) | MQ17: 4110 | MR17: 6725 | MS17: 6668 | MT17: =(MS17-MR17)/MR17 -> -0.0084758364 | MU17: =(MS17-MQ17)/MQ17 -> 0.62238443 | MX17: 지육(원/kg) | MY17: 4104 | MZ17: 6668 | NA17: 6713 | NB17: =(NA17-MZ17)/MZ17 -> 0.0067486503 | NC17: =(NA17-MY17)/MY17 -> 0.63572125 | NF17: 지육(원/kg) | NG17: 3983 | NH17: 6713 | NI17: 6567 | NJ17: =(NI17-NH17)/NH17 -> -0.021748846 | NK17: =(NI17-NG17)/NG17 -> 0.64875722 | NN17: 지육(원/kg) | NO17: 4065 | NP17: 6567 | NQ17: 6399 | NR17: =(NQ17-NP17)/NP17 -> -0.025582458 | NS17: =(NQ17-NO17)/NO17 -> 0.57416974 | NV17: 지육(원/kg) | NW17: 4058 | NX17: 6399 | NY17: 6455 | NZ17: =(NY17-NX17)/NX17 -> 0.0087513674 | OA17: =(NY17-NW17)/NW17 -> 0.59068507 | OD17: 지육(원/kg) | OE17: 3861 | OF17: 6455 | OG17: 6796 | OH17: =(OG17-OF17)/OF17 -> 0.052827266 | OI17: =(OG17-OE17)/OE17 -> 0.76016576 | OL17: 지육(원/kg) | OM17: - | ON17: - | OP17: =(OO17-ON17)/ON17 -> #VALUE! | OQ17: =(OO17-OM17)/OM17 -> #VALUE!
FE19: 돼지/미국 | FM19: 돼지/미국 | FU19: 돼지/미국 | GC19: 돼지/미국 | GK19: 돼지/미국 | GS19: 돼지/미국 | HA19: 돼지/미국 | HI19: 돼지/미국 | HQ19: 돼지/미국 | HY19: 돼지/미국 | IG19: 돼지/미국 | IO19: 돼지/미국 | IW19: 돼지/미국 | JE19: 돼지/미국 | JM19: 돼지/미국 | JU19: 돼지/미국 | KC19: 돼지/미국 | KK19: 돼지/미국 | KS19: 돼지/미국 | LA19: 돼지/미국 | LI19: 돼지/미국 | LQ19: 돼지/미국 | LY19: 돼지/미국 | MG19: 돼지/미국 | MO19: 돼지/미국 | MW19: 돼지/미국 | NE19: 돼지/미국 | NM19: 돼지/미국 | NU19: 돼지/미국 | OC19: 돼지/미국 | OK19: 돼지/미국
FE20: 구분 | FG20: 2019년 | FH20: 2020년 | FJ20: 전주 | FK20: 전년 | FM20: 구분 | FO20: 2019년 | FP20: 2020년 | FR20: 전주 | FS20: 전년 | FU20: 구분 | FW20: 2019년 | FX20: 2020년 | FZ20: 전주 | GA20: 전년 | GC20: 구분 | GE20: 2019년 | GF20: 2020년 | GH20: 전주 | GI20: 전년 | GK20: 구분 | GM20: 2019년 | GN20: 2020년 | GP20: 전주 | GQ20: 전년 | GS20: 구분 | GU20: 2019년 | GV20: 2020년 | GX20: 전주 | GY20: 전년 | HA20: 구분 | HC20: 2019년 | HD20: 2020년 | HF20: 전주 | HG20: 전년 | HI20: 구분 | HK20: 2019년 | HL20: 2020년 | HN20: 전주 | HO20: 전년 | HQ20: 구분 | HS20: 2019년 | HT20: 2020년 | HV20: 전주 | HW20: 전년 | HY20: 구분 | IA20: 2019년 | IB20: 2020년 | ID20: 전주 | IE20: 전년 | IG20: 구분 | II20: 2019년 | IJ20: 2020년 | IL20: 전주 | IM20: 전년 | IO20: 구분 | IQ20: 2019년 | IR20: 2020년 | IT20: 전주 | IU20: 전년 | IW20: 구분 | IY20: 2019년 | IZ20: 2020년 | JB20: 전주 | JC20: 전년 | JE20: 구분 | JG20: 2019년 | JH20: 2020년 | JJ20: 전주 | JK20: 전년 | JM20: 구분 | JO20: 2019년 | JP20: 2020년 | JR20: 전주 | JS20: 전년 | JU20: 구분 | JW20: 2019년 | JX20: 2020년 | JZ20: 전주 | KA20: 전년 | KC20: 구분 | KE20: 2019년 | KF20: 2020년 | KH20: 전주 | KI20: 전년 | KK20: 구분 | KM20: 2019년 | KN20: 2020년 | KP20: 전주 | KQ20: 전년 | KS20: 구분 | KU20: 2019년 | KV20: 2020년 | KX20: 전주 | KY20: 전년 | LA20: 구분 | LC20: 2019년 | LD20: 2020년 | LF20: 전주 | LG20: 전년 | LI20: 구분 | LK20: 2019년 | LL20: 2020년 | LN20: 전주 | LO20: 전년 | LQ20: 구분 | LS20: 2019년 | LT20: 2020년 | LV20: 전주 | LW20: 전년 | LY20: 구분 | MA20: 2019년 | MB20: 2020년 | MD20: 전주 | ME20: 전년 | MG20: 구분 | MI20: 2019년 | MJ20: 2020년 | ML20: 전주 | MM20: 전년 | MO20: 구분 | MQ20: 2019년 | MR20: 2020년 | MT20: 전주 | MU20: 전년 | MW20: 구분 | MY20: 2019년 | MZ20: 2020년 | NB20: 전주 | NC20: 전년 | NE20: 구분 | NG20: 2019년 | NH20: 2020년 | NJ20: 전주 | NK20: 전년 | NM20: 구분 | NO20: 2019년 | NP20: 2020년 | NR20: 전주 | NS20: 전년 | NU20: 구분 | NW20: 2019년 | NX20: 2020년 | NZ20: 전주 | OA20: 전년 | OC20: 구분 | OE20: 2019년 | OF20: 2020년 | OH20: 전주 | OI20: 전년 | OK20: 구분 | OM20: 2019년 | ON20: 2020년 | OP20: 전주 | OQ20: 전년
FG21: 5월4주 | FH21: 5월3주 | FI21: 5월4주 | FJ21: 대비 | FK21: 대비 | FO21: 6월1주 | FP21: 5월4주 | FQ21: 6월1주 | FR21: 대비 | FS21: 대비 | FW21: 6월2주 | FX21: 6월1주 | FY21: 6월2주 | FZ21: 대비 | GA21: 대비 | GE21: 6월3주 | GF21: 6월2주 | GG21: 6월3주 | GH21: 대비 | GI21: 대비 | GM21: 6월4주 | GN21: 6월3주 | GO21: 6월4주 | GP21: 대비 | GQ21: 대비 | GU21: 7월1주 | GV21: 6월4주 | GW21: 7월1주 | GX21: 대비 | GY21: 대비 | HC21: 7월2주 | HD21: 7월1주 | HE21: 7월2주 | HF21: 대비 | HG21: 대비 | HK21: 7월3주 | HL21: 7월2주 | HM21: 7월3주 | HN21: 대비 | HO21: 대비 | HS21: 7월 4주 | HT21: 7월3주 | HU21: 7월 4주 | HV21: 대비 | HW21: 대비 | IA21: 7월 5주 | IB21: 7월 4주 | IC21: 7월 5주 | ID21: 대비 | IE21: 대비 | II21: 8월 1주 | IJ21: 7월 5주 | IK21: 8월 1주 | IL21: 대비 | IM21: 대비 | IQ21: 8월 2주 | IR21: 8월 1주 | IS21: 8월 2주 | IT21: 대비 | IU21: 대비 | IY21: 8월 3주 | IZ21: 8월 2주 | JA21: 8월 3주 | JB21: 대비 | JC21: 대비 | JG21: 8월 4주 | JH21: 8월 3주 | JI21: 8월 4주 | JJ21: 대비 | JK21: 대비 | JO21: 9월 1주 | JP21: 8월 4주 | JQ21: 9월 1주 | JR21: 대비 | JS21: 대비 | JW21: 9월 2주 | JX21: 9월 1주 | JY21: 9월 2주 | JZ21: 대비 | KA21: 대비 | KE21: 9월 3주 | KF21: 9월 2주 | KG21: 9월 3주 | KH21: 대비 | KI21: 대비 | KM21: 9월 4주 | KN21: 9월 3주 | KO21: 9월 4주 | KP21: 대비 | KQ21: 대비 | KU21: 9월 5주 | KV21: 9월 4주 | KW21: 9월 5주 | KX21: 대비 | KY21: 대비 | LC21: 10월1주 | LD21: 9월 5주 | LE21: 10월1주 | LF21: 대비 | LG21: 대비 | LK21: 10월2주 | LL21: 10월1주 | LM21: 10월2주 | LN21: 대비 | LO21: 대비 | LS21: 10월3주 | LT21: 10월2주 | LU21: 10월3주 | LV21: 대비 | LW21: 대비 | MA21: 10월4주 | MB21: 10월3주 | MC21: 10월4주 | MD21: 대비 | ME21: 대비 | MI21: 11월1주 | MJ21: 10월4주 | MK21: 11월1주 | ML21: 대비 | MM21: 대비 | MQ21: 11월2주 | MR21: 11월1주 | MS21: 11월2주 | MT21: 대비 | MU21: 대비 | MY21: 11월3주 | MZ21: 11월2주 | NA21: 11월3주 | NB21: 대비 | NC21: 대비 | NG21: 11월4주 | NH21: 11월3주 | NI21: 11월4주 | NJ21: 대비 | NK21: 대비 | NO21: 12월1주 | NP21: 11월4주 | NQ21: 12월1주 | NR21: 대비 | NS21: 대비 | NW21: 12월2주 | NX21: 12월1주 | NY21: 12월2주 | NZ21: 대비 | OA21: 대비 | OE21: 12월3주 | OF21: 12월2주 | OG21: 12월3주 | OH21: 대비 | OI21: 대비 | OM21: 12월4주 | ON21: 12월3주 | OO21: 12월4주 | OP21: 대비 | OQ21: 대비
FE22: 수급 | FF22: 도축(천두) | FG22: 2325 | FH22: 2137 | FI22: 1966 | FJ22: =(FI22-FH22)/FH22 -> -0.080018718 | FK22: =(FI22-FG22)/FG22 -> -0.1544086 | FM22: 수급 | FN22: 도축(천두) | FO22: 2128 | FP22: 1949 | FQ22: 2452 | FR22: =(FQ22-FP22)/FP22 -> 0.25808107 | FS22: =(FQ22-FO22)/FO22 -> 0.15225564 | FU22: 수급 | FV22: 도축(천두) | FW22: 2417 | FX22: 2442 | FY22: 2457 | FZ22: =(FY22-FX22)/FX22 -> 0.0061425061 | GA22: =(FY22-FW22)/FW22 -> 0.016549441 | GC22: 수급 | GD22: 도축(천두) | GE22: 2431 | GF22: 2451 | GG22: 2587 | GH22: =(GG22-GF22)/GF22 -> 0.055487556 | GI22: =(GG22-GE22)/GE22 -> 0.064171123 | GK22: 수급 | GL22: 도축(천두) | GM22: 2449 | GN22: 2587 | GO22: 2641 | GP22: =(GO22-GN22)/GN22 -> 0.020873599 | GQ22: =(GO22-GM22)/GM22 -> 0.078399347 | GS22: 수급 | GT22: 도축(천두) | GU22: 2384 | GV22: 2641 | GW22: 2043 | GX22: =(GW22-GV22)/GV22 -> -0.22642938 | GY22: =(GW22-GU22)/GU22 -> -0.14303691 | HA22: 수급 | HB22: 도축(천두) | HC22: 2072 | HD22: 2043 | HE22: 2593 | HF22: =(HE22-HD22)/HD22 -> 0.26921194 | HG22: =(HE22-HC22)/HC22 -> 0.25144788 | HI22: 수급 | HJ22: 도축(천두) | HK22: 2415 | HL22: 2593 | HM22: 2518 | HN22: =(HM22-HL22)/HL22 -> -0.028924026 | HO22: =(HM22-HK22)/HK22 -> 0.042650104 | HQ22: 수급 | HR22: 도축(천두) | HS22: 2303 | HT22: 2518 | HU22: 2583 | HV22: =(HU22-HT22)/HT22 -> 0.025814138 | HW22: =(HU22-HS22)/HS22 -> 0.12158055 | HY22: 수급 | HZ22: 도축(천두) | IA22: 2362 | IB22: 2583 | IC22: 2543 | ID22: =(IC22-IB22)/IB22 -> -0.015485869 | IE22: =(IC22-IA22)/IA22 -> 0.076629975 | IG22: 수급 | IH22: 도축(천두) | II22: 2356 | IJ22: 2538 | IK22: 2534 | IL22: =(IK22-IJ22)/IJ22 -> -0.0015760441 | IM22: =(IK22-II22)/II22 -> 0.075551783 | IO22: 수급 | IP22: 도축(천두) | IQ22: 2354 | IR22: 2534 | IS22: 2565 | IT22: =(IS22-IR22)/IR22 -> 0.012233623 | IU22: =(IS22-IQ22)/IQ22 -> 0.089634664 | IW22: 수급 | IX22: 도축(천두) | IY22: 2497 | IZ22: 2559 | JA22: 2618 | JB22: =(JA22-IZ22)/IZ22 -> 0.023055881 | JC22: =(JA22-IY22)/IY22 -> 0.04845815 | JE22: 수급 | JF22: 도축(천두) | JG22: 2528 | JH22: 2618 | JI22: 2664 | JJ22: =(JI22-JH22)/JH22 -> 0.017570665 | JK22: =(JI22-JG22)/JG22 -> 0.053797468 | JM22: 수급 | JN22: 도축(천두) | JO22: 2461 | JP22: 2657 | JQ22: 2484 | JR22: =(JQ22-JP22)/JP22 -> -0.065111027 | JS22: =(JQ22-JO22)/JO22 -> 0.0093457944 | JU22: 수급 | JV22: 도축(천두) | JW22: 2204 | JX22: 2475 | JY22: 2335 | JZ22: =(JY22-JX22)/JX22 -> -0.056565657 | KA22: =(JY22-JW22)/JW22 -> 0.059437387 | KC22: 수급 | KD22: 도축(천두) | KE22: 2611 | KF22: 2323 | KG22: 2587 | KH22: =(KG22-KF22)/KF22 -> 0.11364615 | KI22: =(KG22-KE22)/KE22 -> -0.0091918805 | KK22: 수급 | KL22: 도축(천두) | KM22: 2587 | KN22: 2578 | KO22: 2627 | KP22: =(KO22-KN22)/KN22 -> 0.019006982 | KQ22: =(KO22-KM22)/KM22 -> 0.015461925 | KS22: 수급 | KT22: 도축(천두) | KU22: 2646 | KV22: 2601 | KW22: 2603 | KX22: =(KW22-KV22)/KV22 -> 0.00076893502 | KY22: =(KW22-KU22)/KU22 -> -0.016250945 | LA22: 수급 | LB22: 도축(천두) | LC22: 2669 | LD22: 2603 | LE22: 2730 | LF22: =(LE22-LD22)/LD22 -> 0.048789858 | LG22: =(LE22-LC22)/LC22 -> 0.022855002 | LI22: 수급 | LJ22: 도축(천두) | LK22: 2725 | LL22: 2730 | LM22: 2688 | LN22: =(LM22-LL22)/LL22 -> -0.015384615 | LO22: =(LM22-LK22)/LK22 -> -0.013577982 | LQ22: 수급 | LR22: 도축(천두) | LS22: 2726 | LT22: 2688 | LU22: 2679 | LV22: =(LU22-LT22)/LT22 -> -0.0033482143 | LW22: =(LU22-LS22)/LS22 -> -0.017241379 | LY22: 수급 | LZ22: 도축(천두) | MA22: 2693 | MB22: 2672 | MC22: 2683 | MD22: =(MC22-MB22)/MB22 -> 0.0041167665 | ME22: =(MC22-MA22)/MA22 -> -0.0037133309 | MG22: 수급 | MH22: 도축(천두) | MI22: 2669 | MJ22: 2683 | MK22: 2713 | ML22: =(MK22-MJ22)/MJ22 -> 0.011181513 | MM22: =(MK22-MI22)/MI22 -> 0.016485575 | MO22: 수급 | MP22: 도축(천두) | MQ22: 2693 | MR22: 2713 | MS22: 2688 | MT22: =(MS22-MR22)/MR22 -> -0.0092148913 | MU22: =(MS22-MQ22)/MQ22 -> -0.0018566654 | MW22: 수급 | MX22: 도축(천두) | MY22: 2749 | MZ22: 2683 | NA22: 2711 | NB22: =(NA22-MZ22)/MZ22 -> 0.010436079 | NC22: =(NA22-MY22)/MY22 -> -0.013823208 | NE22: 수급 | NF22: 도축(천두) | NG22: 2758 | NH22: 2711 | NI22: 2350 | NJ22: =(NI22-NH22)/NH22 -> -0.1331612 | NK22: =(NI22-NG22)/NG22 -> -0.14793328 | NM22: 수급 | NN22: 도축(천두) | NO22: 2343 | NP22: 2350 | NQ22: 2789 | NR22: =(NQ22-NP22)/NP22 -> 0.18680851 | NS22: =(NQ22-NO22)/NO22 -> 0.19035425 | NU22: 수급 | NV22: 도축(천두) | NW22: 2799 | NX22: 2777 | NY22: 2776 | NZ22: =(NY22-NX22)/NX22 -> -0.00036010083 | OA22: =(NY22-NW22)/NW22 -> -0.0082172204 | OC22: 수급 | OD22: 도축(천두) | OE22: 2763 | OF22: 2762 | OG22: 2792 | OH22: =(OG22-OF22)/OF22 -> 0.010861694 | OI22: =(OG22-OE22)/OE22 -> 0.010495838 | OK22: 수급 | OL22: 도축(천두) | OM22: 2810 | ON22: 2787 | OO22: 1740 | OP22: =(OO22-ON22)/ON22 -> -0.37567277 | OQ22: =(OO22-OM22)/OM22 -> -0.38078292
FF23: 수출(천톤) | FJ23: =(FI23-FH23)/FH23 -> #DIV/0! | FK23: =(FI23-FG23)/FG23 -> #DIV/0! | FN23: 수출(천톤) | FR23: =(FQ23-FP23)/FP23 -> #DIV/0! | FS23: =(FQ23-FO23)/FO23 -> #DIV/0! | FV23: 수출(천톤) | FZ23: =(FY23-FX23)/FX23 -> #DIV/0! | GA23: =(FY23-FW23)/FW23 -> #DIV/0! | GD23: 수출(천톤) | GH23: =(GG23-GF23)/GF23 -> #DIV/0! | GI23: =(GG23-GE23)/GE23 -> #DIV/0! | GL23: 수출(천톤) | GP23: =(GO23-GN23)/GN23 -> #DIV/0! | GQ23: =(GO23-GM23)/GM23 -> #DIV/0! | GT23: 수출(천톤) | GX23: =(GW23-GV23)/GV23 -> #DIV/0! | GY23: =(GW23-GU23)/GU23 -> #DIV/0! | HB23: 수출(천톤) | HF23: =(HE23-HD23)/HD23 -> #DIV/0! | HG23: =(HE23-HC23)/HC23 -> #DIV/0! | HJ23: 수출(천톤) | HN23: =(HM23-HL23)/HL23 -> #DIV/0! | HO23: =(HM23-HK23)/HK23 -> #DIV/0! | HR23: 수출(천톤) | HV23: =(HU23-HT23)/HT23 -> #DIV/0! | HW23: =(HU23-HS23)/HS23 -> #DIV/0! | HZ23: 수출(천톤) | ID23: =(IC23-IB23)/IB23 -> #DIV/0! | IE23: =(IC23-IA23)/IA23 -> #DIV/0! | IH23: 수출(천톤) | IL23: =(IK23-IJ23)/IJ23 -> #DIV/0! | IM23: =(IK23-II23)/II23 -> #DIV/0! | IP23: 수출(천톤) | IT23: =(IS23-IR23)/IR23 -> #DIV/0! | IU23: =(IS23-IQ23)/IQ23 -> #DIV/0! | IX23: 수출(천톤) | JB23: =(JA23-IZ23)/IZ23 -> #DIV/0! | JC23: =(JA23-IY23)/IY23 -> #DIV/0! | JF23: 수출(천톤) | JJ23: =(JI23-JH23)/JH23 -> #DIV/0! | JK23: =(JI23-JG23)/JG23 -> #DIV/0! | JN23: 수출(천톤) | JR23: =(JQ23-JP23)/JP23 -> #DIV/0! | JS23: =(JQ23-JO23)/JO23 -> #DIV/0! | JV23: 수출(천톤) | JZ23: =(JY23-JX23)/JX23 -> #DIV/0! | KA23: =(JY23-JW23)/JW23 -> #DIV/0! | KD23: 수출(천톤) | KH23: =(KG23-KF23)/KF23 -> #DIV/0! | KI23: =(KG23-KE23)/KE23 -> #DIV/0! | KL23: 수출(천톤) | KP23: =(KO23-KN23)/KN23 -> #DIV/0! | KQ23: =(KO23-KM23)/KM23 -> #DIV/0! | KT23: 수출(천톤) | KX23: =(KW23-KV23)/KV23 -> #DIV/0! | KY23: =(KW23-KU23)/KU23 -> #DIV/0! | LB23: 수출(천톤) | LF23: =(LE23-LD23)/LD23 -> #DIV/0! | LG23: =(LE23-LC23)/LC23 -> #DIV/0! | LJ23: 수출(천톤) | LN23: =(LM23-LL23)/LL23 -> #DIV/0! | LO23: =(LM23-LK23)/LK23 -> #DIV/0! | LR23: 수출(천톤) | LV23: =(LU23-LT23)/LT23 -> #DIV/0! | LW23: =(LU23-LS23)/LS23 -> #DIV/0! | LZ23: 수출(천톤) | MD23: =(MC23-MB23)/MB23 -> #DIV/0! | ME23: =(MC23-MA23)/MA23 -> #DIV/0! | MH23: 수출(천톤) | ML23: =(MK23-MJ23)/MJ23 -> #DIV/0! | MM23: =(MK23-MI23)/MI23 -> #DIV/0! | MP23: 수출(천톤) | MT23: =(MS23-MR23)/MR23 -> #DIV/0! | MU23: =(MS23-MQ23)/MQ23 -> #DIV/0! | MX23: 수출(천톤) | NB23: =(NA23-MZ23)/MZ23 -> #DIV/0! | NC23: =(NA23-MY23)/MY23 -> #DIV/0! | NF23: 수출(천톤) | NJ23: =(NI23-NH23)/NH23 -> #DIV/0! | NK23: =(NI23-NG23)/NG23 -> #DIV/0! | NN23: 수출(천톤) | NR23: =(NQ23-NP23)/NP23 -> #DIV/0! | NS23: =(NQ23-NO23)/NO23 -> #DIV/0! | NV23: 수출(천톤) | NZ23: =(NY23-NX23)/NX23 -> #DIV/0! | OA23: =(NY23-NW23)/NW23 -> #DIV/0! | OD23: 수출(천톤) | OH23: =(OG23-OF23)/OF23 -> #DIV/0! | OI23: =(OG23-OE23)/OE23 -> #DIV/0! | OL23: 수출(천톤) | OP23: =(OO23-ON23)/ON23 -> #DIV/0! | OQ23: =(OO23-OM23)/OM23 -> #DIV/0!
FE24: 가격 | FF24: 생돈($/lb) | FG24: 0.78 | FH24: 0.39 | FI24: 0.37 | FJ24: =(FI24-FH24)/FH24 -> -0.051282051 | FK24: =(FI24-FG24)/FG24 -> -0.52564103 | FM24: 가격 | FN24: 지육($/kg) | FR24: =(FQ24-FP24)/FP24 -> #DIV/0! | FS24: =(FQ24-FO24)/FO24 -> #DIV/0! | FU24: 가격 | FV24: 지육($/kg) | FZ24: =(FY24-FX24)/FX24 -> #DIV/0! | GA24: =(FY24-FW24)/FW24 -> #DIV/0! | GC24: 가격 | GD24: 지육($/kg) | GE24: 1.83 | GF24: 1.54 | GG24: 1.43 | GH24: =(GG24-GF24)/GF24 -> -0.071428571 | GI24: =(GG24-GE24)/GE24 -> -0.21857923 | GK24: 가격 | GL24: 지육($/kg) | GM24: 1.74 | GN24: 1.43 | GO24: 1.43 | GP24: =(GO24-GN24)/GN24 -> 0 | GQ24: =(GO24-GM24)/GM24 -> -0.17816092 | GS24: 가격 | GT24: 지육($/kg) | GU24: 1.65 | GV24: 1.43 | GW24: 1.43 | GX24: =(GW24-GV24)/GV24 -> 0 | GY24: =(GW24-GU24)/GU24 -> -0.13333333 | HA24: 가격 | HB24: 지육($/kg) | HC24: 1.61 | HD24: 1.43 | HE24: 1.46 | HF24: =(HE24-HD24)/HD24 -> 0.020979021 | HG24: =(HE24-HC24)/HC24 -> -0.093167702 | HI24: 가격 | HJ24: 지육($/kg) | HK24: 1.59 | HL24: 1.46 | HM24: 1.5 | HN24: =(HM24-HL24)/HL24 -> 0.02739726 | HO24: =(HM24-HK24)/HK24 -> -0.056603774 | HQ24: 가격 | HR24: 지육($/kg) | HS24: 1.68 | HT24: 1.5 | HU24: 1.54 | HV24: =(HU24-HT24)/HT24 -> 0.026666667 | HW24: =(HU24-HS24)/HS24 -> -0.083333333 | HY24: 가격 | HZ24: 지육($/kg) | IA24: 1.81 | IB24: 1.54 | IC24: 1.5 | ID24: =(IC24-IB24)/IB24 -> -0.025974026 | IE24: =(IC24-IA24)/IA24 -> -0.17127072 | IG24: 가격 | IH24: 지육($/kg) | II24: 1.92 | IJ24: 1.5 | IK24: 1.5 | IL24: =(IK24-IJ24)/IJ24 -> 0 | IM24: =(IK24-II24)/II24 -> -0.21875 | IO24: 가격 | IP24: 지육($/kg) | IQ24: 1.96 | IR24: 1.5 | IS24: 1.59 | IT24: =(IS24-IR24)/IR24 -> 0.06 | IU24: =(IS24-IQ24)/IQ24 -> -0.18877551 | IW24: 가격 | IX24: 지육($/kg) | IY24: 1.96 | IZ24: 1.59 | JA24: 1.65 | JB24: =(JA24-IZ24)/IZ24 -> 0.037735849 | JC24: =(JA24-IY24)/IY24 -> -0.15816327 | JE24: 가격 | JF24: 지육($/kg) | JG24: 1.81 | JH24: 1.65 | JI24: 1.61 | JJ24: =(JI24-JH24)/JH24 -> -0.024242424 | JK24: =(JI24-JG24)/JG24 -> -0.11049724 | JM24: 가격 | JN24: 지육($/kg) | JO24: 1.63 | JP24: 1.61 | JQ24: 1.68 | JR24: =(JQ24-JP24)/JP24 -> 0.043478261 | JS24: =(JQ24-JO24)/JO24 -> 0.030674847 | JU24: 가격 | JV24: 지육($/kg) | JW24: 1.61 | JX24: 1.68 | JY24: 1.79 | JZ24: =(JY24-JX24)/JX24 -> 0.06547619 | KA24: =(JY24-JW24)/JW24 -> 0.11180124 | KC24: 가격 | KD24: 지육($/kg) | KE24: 1.57 | KF24: 1.79 | KG24: 1.85 | KH24: =(KG24-KF24)/KF24 -> 0.033519553 | KI24: =(KG24-KE24)/KE24 -> 0.17834395 | KK24: 가격 | KL24: 지육($/kg) | KM24: 1.52 | KN24: 1.85 | KO24: 1.98 | KP24: =(KO24-KN24)/KN24 -> 0.07027027 | KQ24: =(KO24-KM24)/KM24 -> 0.30263158 | KS24: 가격 | KT24: 지육($/kg) | KU24: 1.57 | KV24: 1.98 | KW24: 2.05 | KX24: =(KW24-KV24)/KV24 -> 0.035353535 | KY24: =(KW24-KU24)/KU24 -> 0.30573248 | LA24: 가격 | LB24: 지육($/kg) | LC24: 1.65 | LD24: 2.05 | LE24: 2.09 | LF24: =(LE24-LD24)/LD24 -> 0.019512195 | LG24: =(LE24-LC24)/LC24 -> 0.26666667 | LI24: 가격 | LJ24: 지육($/kg) | LK24: 1.7 | LL24: 2.09 | LM24: 2.14 | LN24: =(LM24-LL24)/LL24 -> 0.023923445 | LO24: =(LM24-LK24)/LK24 -> 0.25882353 | LQ24: 가격 | LR24: 지육($/kg) | LS24: 1.7 | LT24: 2.14 | LU24: 2.14 | LV24: =(LU24-LT24)/LT24 -> 0 | LW24: =(LU24-LS24)/LS24 -> 0.25882353 | LY24: 가격 | LZ24: 지육($/kg) | MA24: 1.68 | MB24: 2.14 | MC24: 1.92 | MD24: =(MC24-MB24)/MB24 -> -0.10280374 | ME24: =(MC24-MA24)/MA24 -> 0.14285714 | MG24: 가격 | MH24: 지육($/kg) | MI24: 1.68 | MJ24: 1.92 | MK24: 1.85 | ML24: =(MK24-MJ24)/MJ24 -> -0.036458333 | MM24: =(MK24-MI24)/MI24 -> 0.10119048 | MO24: 가격 | MP24: 지육($/kg) | MQ24: 1.79 | MR24: 1.85 | MS24: 1.83 | MT24: =(MS24-MR24)/MR24 -> -0.010810811 | MU24: =(MS24-MQ24)/MQ24 -> 0.022346369 | MW24: 가격 | MX24: 지육($/kg) | MY24: 1.92 | MZ24: 1.83 | NA24: 1.74 | NB24: =(NA24-MZ24)/MZ24 -> -0.049180328 | NC24: =(NA24-MY24)/MY24 -> -0.09375 | NE24: 가격 | NF24: 지육($/kg) | NG24: 1.87 | NH24: 1.74 | NI24: 1.72 | NJ24: =(NI24-NH24)/NH24 -> -0.011494253 | NK24: =(NI24-NG24)/NG24 -> -0.080213904 | NM24: 가격 | NN24: 지육($/kg) | NO24: 1.81 | NP24: 1.72 | NQ24: 1.72 | NR24: =(NQ24-NP24)/NP24 -> 0 | NS24: =(NQ24-NO24)/NO24 -> -0.049723757 | NU24: 가격 | NV24: 지육($/kg) | NW24: 1.81 | NX24: 1.72 | NY24: 1.72 | NZ24: =(NY24-NX24)/NX24 -> 0 | OA24: =(NY24-NW24)/NW24 -> -0.049723757 | OC24: 가격 | OD24: 지육($/kg) | OE24: 1.81 | OF24: 1.72 | OG24: 1.63 | OH24: =(OG24-OF24)/OF24 -> -0.052325581 | OI24: =(OG24-OE24)/OE24 -> -0.099447514 | OK24: 가격 | OL24: 지육($/kg) | OM24: 1.72 | ON24: 1.63 | OO24: 1.54 | OP24: =(OO24-ON24)/ON24 -> -0.055214724 | OQ24: =(OO24-OM24)/OM24 -> -0.10465116
FF25: 지육($/lb) | FG25: 0.85 | FH25: 1 | FI25: 0.91 | FJ25: =(FI25-FH25)/FH25 -> -0.09 | FK25: =(FI25-FG25)/FG25 -> 0.070588235 | FN25: 지육(원/kg) | FO25: 2182 | FP25: 2442 | FQ25: 1999 | FR25: =(FQ25-FP25)/FP25 -> -0.18140868 | FS25: =(FQ25-FO25)/FO25 -> -0.083868011 | FV25: 지육(원/kg) | FW25: 1996 | FX25: 1999 | FY25: 1830 | FZ25: =(FY25-FX25)/FX25 -> -0.084542271 | GA25: =(FY25-FW25)/FW25 -> -0.083166333 | GD25: 지육(원/kg) | GE25: 2153 | GF25: 1830 | GG25: 1728 | GH25: =(GG25-GF25)/GF25 -> -0.055737705 | GI25: =(GG25-GE25)/GE25 -> -0.19739898 | GL25: 지육(원/kg) | GM25: 2014 | GN25: 1728 | GO25: 1725 | GP25: =(GO25-GN25)/GN25 -> -0.0017361111 | GQ25: =(GO25-GM25)/GM25 -> -0.14349553 | GT25: 지육(원/kg) | GU25: 1935 | GV25: 1725 | GW25: 1712 | GX25: =(GW25-GV25)/GV25 -> -0.0075362319 | GY25: =(GW25-GU25)/GU25 -> -0.11524548 | HB25: 지육(원/kg) | HC25: 1901 | HD25: 1712 | HE25: 1748 | HF25: =(HE25-HD25)/HD25 -> 0.021028037 | HG25: =(HE25-HC25)/HC25 -> -0.080483956 | HJ25: 지육(원/kg) | HK25: 1875 | HL25: 1748 | HM25: 1794 | HN25: =(HM25-HL25)/HL25 -> 0.026315789 | HO25: =(HM25-HK25)/HK25 -> -0.0432 | HR25: 지육(원/kg) | HS25: 1975 | HT25: 1794 | HU25: 1844 | HV25: =(HU25-HT25)/HT25 -> 0.02787068 | HW25: =(HU25-HS25)/HS25 -> -0.066329114 | HZ25: 지육(원/kg) | IA25: 2139 | IB25: 1844 | IC25: 1781 | ID25: =(IC25-IB25)/IB25 -> -0.034164859 | IE25: =(IC25-IA25)/IA25 -> -0.16736793 | IH25: 지육(원/kg) | II25: 2331 | IJ25: 1781 | IK25: 1776 | IL25: =(IK25-IJ25)/IJ25 -> -0.0028074116 | IM25: =(IK25-II25)/II25 -> -0.23809524 | IP25: 지육(원/kg) | IQ25: 2384 | IR25: 1776 | IS25: 1875 | IT25: =(IS25-IR25)/IR25 -> 0.055743243 | IU25: =(IS25-IQ25)/IQ25 -> -0.21350671 | IX25: 지육(원/kg) | IY25: 2361 | IZ25: 1875 | JA25: 1963 | JB25: =(JA25-IZ25)/IZ25 -> 0.046933333 | JC25: =(JA25-IY25)/IY25 -> -0.16857264 | JF25: 지육(원/kg) | JG25: 2196 | JH25: 1963 | JI25: 1910 | JJ25: =(JI25-JH25)/JH25 -> -0.026999491 | JK25: =(JI25-JG25)/JG25 -> -0.13023679 | JN25: 지육(원/kg) | JO25: 1969 | JP25: 1910 | JQ25: 1990 | JR25: =(JQ25-JP25)/JP25 -> 0.041884817 | JS25: =(JQ25-JO25)/JO25 -> 0.010665312 | JV25: 지육(원/kg) | JW25: 1922 | JX25: 1990 | JY25: 2096 | JZ25: =(JY25-JX25)/JX25 -> 0.053266332 | KA25: =(JY25-JW25)/JW25 -> 0.090530697 | KD25: 지육(원/kg) | KE25: 1866 | KF25: 2096 | KG25: 2157 | KH25: =(KG25-KF25)/KF25 -> 0.029103053 | KI25: =(KG25-KE25)/KE25 -> 0.15594855 | KL25: 지육(원/kg) | KM25: 1826 | KN25: 2157 | KO25: 2319 | KP25: =(KO25-KN25)/KN25 -> 0.075104312 | KQ25: =(KO25-KM25)/KM25 -> 0.26998905 | KT25: 지육(원/kg) | KU25: 1889 | KV25: 2319 | KW25: 2382 | KX25: =(KW25-KV25)/KV25 -> 0.027166882 | KY25: =(KW25-KU25)/KU25 -> 0.26098465 | LB25: 지육(원/kg) | LC25: 1978 | LD25: 2382 | LE25: 2401 | LF25: =(LE25-LD25)/LD25 -> 0.0079764903 | LG25: =(LE25-LC25)/LC25 -> 0.21385238 | LJ25: 지육(원/kg) | LK25: 2019 | LL25: 2401 | LM25: 2424 | LN25: =(LM25-LL25)/LL25 -> 0.0095793419 | LO25: =(LM25-LK25)/LK25 -> 0.20059435 | LR25: 지육(원/kg) | LS25: 1991 | LT25: 2424 | LU25: 2424 | LV25: =(LU25-LT25)/LT25 -> 0 | LW25: =(LU25-LS25)/LS25 -> 0.21747865 | LZ25: 지육(원/kg) | MA25: 1954 | MB25: 2424 | MC25: 2187 | MD25: =(MC25-MB25)/MB25 -> -0.097772277 | ME25: =(MC25-MA25)/MA25 -> 0.11924258 | MH25: 지육(원/kg) | MI25: 1941 | MJ25: 2187 | MK25: 2061 | ML25: =(MK25-MJ25)/MJ25 -> -0.057613169 | MM25: =(MK25-MI25)/MI25 -> 0.061823802 | MP25: 지육(원/kg) | MQ25: 2088 | MR25: 2061 | MS25: 2019 | MT25: =(MS25-MR25)/MR25 -> -0.020378457 | MU25: =(MS25-MQ25)/MQ25 -> -0.033045977 | MX25: 지육(원/kg) | MY25: 2245 | MZ25: 2019 | NA25: 1928 | NB25: =(NA25-MZ25)/MZ25 -> -0.045071818 | NC25: =(NA25-MY25)/MY25 -> -0.14120267 | NF25: 지육(원/kg) | NG25: 2207 | NH25: 1928 | NI25: 1897 | NJ25: =(NI25-NH25)/NH25 -> -0.016078838 | NK25: =(NI25-NG25)/NG25 -> -0.14046217 | NN25: 지육(원/kg) | NO25: 2157 | NP25: 1897 | NQ25: 1866 | NR25: =(NQ25-NP25)/NP25 -> -0.016341592 | NS25: =(NQ25-NO25)/NO25 -> -0.1349096 | NV25: 지육(원/kg) | NW25: 2160 | NX25: 1866 | NY25: 1876 | NZ25: =(NY25-NX25)/NX25 -> 0.0053590568 | OA25: =(NY25-NW25)/NW25 -> -0.13148148 | OD25: 지육(원/kg) | OE25: 2112 | OF25: 1876 | OG25: 1809 | OH25: =(OG25-OF25)/OF25 -> -0.035714286 | OI25: =(OG25-OE25)/OE25 -> -0.14346591 | OL25: 지육(원/kg) | OM25: 2002 | ON25: 1809 | OO25: 1678 | OP25: =(OO25-ON25)/ON25 -> -0.072415699 | OQ25: =(OO25-OM25)/OM25 -> -0.16183816
